Workbook
Name IncCCD1: 'Scenario Inputs'!$G$61
Name IncCCD2: 'Scenario Inputs'!$G$62
Name IncCCD3: 'Scenario Inputs'!$G$63
Name IncCCD4: 'Scenario Inputs'!$G$64
Name IncCCD5: 'Scenario Inputs'!$G$65
Name IncCCD6: 'Scenario Inputs'!$G$66
Name IncHHD: 'Cost Inputs'!#REF!
Name IncHHD: 'Scenario Inputs'!$G$49
Name IncLP: 'Scenario Inputs'!$G$67
Name IncPD: 'Scenario Inputs'!$G$52
Name IncPEcad: 'Scenario Inputs'!$G$97
Name IncPElive: 'Scenario Inputs'!$G$94

Sheet Cover Sheet

Sheet Background

Sheet DES Pathway Map

Sheet Costing Map

Sheet Methods Overview

Sheet simPy_sheet
A2: simulation duration | B2: =('Scenario Inputs'!R23-'Scenario Inputs'!R21)*365 + 365 -> 4745 | C2: days | D2: Region | E2: ='Scenario Inputs'!F20 -> Fictional Region | F2: Centre | G2: ='Scenario Inputs'!F21 -> Fictional Centre | P2: CURRENTLY PULLING THESE VALUES
P3: NEED TO ADD THESE
B4: 1 | C4: 2 | D4: 3 | E4: 4 | F4: 5 | G4: 6 | H4: 7 | I4: 8 | J4: 9 | K4: 10 | L4: 11 | M4: 12 | N4: 13
A5: Incidence Profile | B5: =daily_rate!A2 -> 0.5 | C5: =daily_rate!B2 -> 0.5 | D5: =daily_rate!C2 -> 0.5 | E5: =daily_rate!D2 -> 0.5 | F5: =daily_rate!E2 -> 0.5 | G5: =daily_rate!F2 -> 0.5 | H5: =daily_rate!G2 -> 0.5 | I5: =daily_rate!H2 -> 0.5 | ... N5: =daily_rate!M2 -> 0.5 | O5: validation
B6: =IF('Scenario Inputs'!I38="",daily_rate!N2,daily_rate!N2) -> 0.5 | C6: =IF('Scenario Inputs'!J38="",daily_rate!O2,daily_rate!O2) -> 0.5 | D6: =IF('Scenario Inputs'!K38="",daily_rate!P2,daily_rate!P2) -> 0.5 | E6: =IF('Scenario Inputs'!L38="",daily_rate!Q2,daily_rate!Q2) -> 0.5 | F6: =IF('Scenario Inputs'!M38="",daily_rate!R2,daily_rate!R2) -> 0.5 | G6: =IF('Scenario Inputs'!N38="",daily_rate!S2,daily_rate!S2) -> 0.5 | H6: =IF('Scenario Inputs'!O38="",daily_rate!T2,daily_rate!T2) -> 0.5 | I6: =IF('Scenario Inputs'!P38="",daily_rate!U2,daily_rate!U2) -> 0.5 | ... N6: =IF('Scenario Inputs'!U38="",daily_rate!Z2,daily_rate!Z2) -> 0.5 | O6: experimentation
A7: Age dist | B7: 1 | C7: 2 | D7: 3 | E7: 4 | F7: 5 | G7: 6
B8: =age_dist!B1 -> 0.05 | C8: =age_dist!B2 -> 0.07 | D8: =age_dist!B3 -> 0.12 | E8: =age_dist!B4 -> 0.2 | F8: =age_dist!B5 -> 0.25 | G8: =age_dist!B6 -> 0.31
A10: Referral | B10: Early | C10: Late
B11: =1-B12 -> 0.8 | C11: =1-C12 -> 0.8 | D11: =1-D12 -> 0.8 | E11: =1-E12 -> 0.8 | F11: =1-F12 -> 0.8 | G11: =1-G12 -> 0.8 | H11: =1-H12 -> 0.8 | I11: =1-I12 -> 0.8 | ... N11: =1-N12 -> 0.8
B12: =IF('Scenario Inputs'!I67="",referral_dist!$B$2,'Scenario Inputs'!I67) -> 0.2 | C12: =IF('Scenario Inputs'!J67="",referral_dist!$B$2,'Scenario Inputs'!J67) -> 0.2 | D12: =IF('Scenario Inputs'!K67="",referral_dist!$B$2,'Scenario Inputs'!K67) -> 0.2 | E12: =IF('Scenario Inputs'!L67="",referral_dist!$B$2,'Scenario Inputs'!L67) -> 0.2 | F12: =IF('Scenario Inputs'!M67="",referral_dist!$B$2,'Scenario Inputs'!M67) -> 0.2 | G12: =IF('Scenario Inputs'!N67="",referral_dist!$B$2,'Scenario Inputs'!N67) -> 0.2 | H12: =IF('Scenario Inputs'!O67="",referral_dist!$B$2,'Scenario Inputs'!O67) -> 0.2 | I12: =IF('Scenario Inputs'!P67="",referral_dist!$B$2,'Scenario Inputs'!P67) -> 0.2 | ... N12: =IF('Scenario Inputs'!U67="",referral_dist!$B$2,'Scenario Inputs'!U67) -> 0.2
A13: Interventions
B14: Rollout year target percentage
B15: 1 | C15: 2 | D15: 3 | E15: 4 | F15: 5 | G15: 6 | H15: 7 | I15: 8 | J15: 9 | K15: 10 | L15: 11 | M15: 12 | N15: 13
A16: Change in HHD allocation probability | B16: =IF('Scenario Inputs'!I49="",IncHHD,'Scenario Inputs'!I49) -> 0.18918919 | C16: =IF('Scenario Inputs'!J49="",IncHHD,'Scenario Inputs'!J49) -> 0.18918919 | D16: =IF('Scenario Inputs'!K49="",IncHHD,'Scenario Inputs'!K49) -> 0.18918919 | E16: =IF('Scenario Inputs'!L49="",IncHHD,'Scenario Inputs'!L49) -> 0.18918919 | F16: =IF('Scenario Inputs'!M49="",IncHHD,'Scenario Inputs'!M49) -> 0.18918919 | G16: =IF('Scenario Inputs'!N49="",IncHHD,'Scenario Inputs'!N49) -> 0.18918919 | H16: =IF('Scenario Inputs'!O49="",IncHHD,'Scenario Inputs'!O49) -> 0.18918919 | I16: =IF('Scenario Inputs'!P49="",IncHHD,'Scenario Inputs'!P49) -> 0.18918919 | ... N16: =IF('Scenario Inputs'!U49="",IncHHD,'Scenario Inputs'!U49) -> 0.18918919
A17: Change in PD allocation probability | B17: {=IF('Scenario Inputs'!I52="",IncPD,'Scenario Inputs'!I52)} -> 0.29 | C17: {=IF('Scenario Inputs'!J52="",IncPD,'Scenario Inputs'!J52)} -> 0.29 | D17: {=IF('Scenario Inputs'!K52="",IncPD,'Scenario Inputs'!K52)} -> 0.29 | E17: {=IF('Scenario Inputs'!L52="",IncPD,'Scenario Inputs'!L52)} -> 0.29 | F17: {=IF('Scenario Inputs'!M52="",IncPD,'Scenario Inputs'!M52)} -> 0.29 | G17: {=IF('Scenario Inputs'!N52="",IncPD,'Scenario Inputs'!N52)} -> 0.29 | H17: {=IF('Scenario Inputs'!O52="",IncPD,'Scenario Inputs'!O52)} -> 0.29 | I17: {=IF('Scenario Inputs'!P52="",IncPD,'Scenario Inputs'!P52)} -> 0.29 | ... N17: {=IF('Scenario Inputs'!U52="",IncPD,'Scenario Inputs'!U52)} -> 0.29
B19: Rollout year target percentage
B20: 1 | C20: 2 | D20: 3 | E20: 4 | F20: 5 | G20: 6 | H20: 7 | I20: 8 | J20: 9 | K20: 10 | L20: 11 | M20: 12 | N20: 13
A21: Change in probability of diverting to conservative care | B21: =IF('Scenario Inputs'!I61="",IncCCD1,'Scenario Inputs'!I61) -> 0.1 | C21: =IF('Scenario Inputs'!J61="",IncCCD1,'Scenario Inputs'!J61) -> 0.1 | D21: =IF('Scenario Inputs'!K61="",IncCCD1,'Scenario Inputs'!K61) -> 0.1 | E21: =IF('Scenario Inputs'!L61="",IncCCD1,'Scenario Inputs'!L61) -> 0.1 | F21: =IF('Scenario Inputs'!M61="",IncCCD1,'Scenario Inputs'!M61) -> 0.1 | G21: =IF('Scenario Inputs'!N61="",IncCCD1,'Scenario Inputs'!N61) -> 0.1 | H21: =IF('Scenario Inputs'!O61="",IncCCD1,'Scenario Inputs'!O61) -> 0.1 | I21: =IF('Scenario Inputs'!P61="",IncCCD1,'Scenario Inputs'!P61) -> 0.1 | ... N21: =IF('Scenario Inputs'!U61="",IncCCD1,'Scenario Inputs'!U61) -> 0.1
B22: =IF('Scenario Inputs'!I62="",IncCCD2,'Scenario Inputs'!I62) -> 0.1 | C22: =IF('Scenario Inputs'!J62="",IncCCD2,'Scenario Inputs'!J62) -> 0.1 | D22: =IF('Scenario Inputs'!K62="",IncCCD2,'Scenario Inputs'!K62) -> 0.1 | E22: =IF('Scenario Inputs'!L62="",IncCCD2,'Scenario Inputs'!L62) -> 0.1 | F22: =IF('Scenario Inputs'!M62="",IncCCD2,'Scenario Inputs'!M62) -> 0.1 | G22: =IF('Scenario Inputs'!N62="",IncCCD2,'Scenario Inputs'!N62) -> 0.1 | H22: =IF('Scenario Inputs'!O62="",IncCCD2,'Scenario Inputs'!O62) -> 0.1 | I22: =IF('Scenario Inputs'!P62="",IncCCD2,'Scenario Inputs'!P62) -> 0.1 | ... N22: =IF('Scenario Inputs'!U62="",IncCCD2,'Scenario Inputs'!U62) -> 0.1
B23: =IF('Scenario Inputs'!I63="",IncCCD3,'Scenario Inputs'!I63) -> 0.1 | C23: =IF('Scenario Inputs'!J63="",IncCCD3,'Scenario Inputs'!J63) -> 0.1 | D23: =IF('Scenario Inputs'!K63="",IncCCD3,'Scenario Inputs'!K63) -> 0.1 | E23: =IF('Scenario Inputs'!L63="",IncCCD3,'Scenario Inputs'!L63) -> 0.1 | F23: =IF('Scenario Inputs'!M63="",IncCCD3,'Scenario Inputs'!M63) -> 0.1 | G23: =IF('Scenario Inputs'!N63="",IncCCD3,'Scenario Inputs'!N63) -> 0.1 | H23: =IF('Scenario Inputs'!O63="",IncCCD3,'Scenario Inputs'!O63) -> 0.1 | I23: =IF('Scenario Inputs'!P63="",IncCCD3,'Scenario Inputs'!P63) -> 0.1 | ... N23: =IF('Scenario Inputs'!U63="",IncCCD3,'Scenario Inputs'!U63) -> 0.1
B24: =IF('Scenario Inputs'!I64="",IncCCD4,'Scenario Inputs'!I64) -> 0.1 | C24: =IF('Scenario Inputs'!J64="",IncCCD4,'Scenario Inputs'!J64) -> 0.1 | D24: =IF('Scenario Inputs'!K64="",IncCCD4,'Scenario Inputs'!K64) -> 0.1 | E24: =IF('Scenario Inputs'!L64="",IncCCD4,'Scenario Inputs'!L64) -> 0.1 | F24: =IF('Scenario Inputs'!M64="",IncCCD4,'Scenario Inputs'!M64) -> 0.1 | G24: =IF('Scenario Inputs'!N64="",IncCCD4,'Scenario Inputs'!N64) -> 0.1 | H24: =IF('Scenario Inputs'!O64="",IncCCD4,'Scenario Inputs'!O64) -> 0.1 | I24: =IF('Scenario Inputs'!P64="",IncCCD4,'Scenario Inputs'!P64) -> 0.1 | ... N24: =IF('Scenario Inputs'!U64="",IncCCD4,'Scenario Inputs'!U64) -> 0.1
B25: =IF('Scenario Inputs'!I65="",IncCCD5,'Scenario Inputs'!I65) -> 0.25 | C25: =IF('Scenario Inputs'!J65="",IncCCD5,'Scenario Inputs'!J65) -> 0.25 | D25: =IF('Scenario Inputs'!K65="",IncCCD5,'Scenario Inputs'!K65) -> 0.25 | E25: =IF('Scenario Inputs'!L65="",IncCCD5,'Scenario Inputs'!L65) -> 0.25 | F25: =IF('Scenario Inputs'!M65="",IncCCD5,'Scenario Inputs'!M65) -> 0.25 | G25: =IF('Scenario Inputs'!N65="",IncCCD5,'Scenario Inputs'!N65) -> 0.25 | H25: =IF('Scenario Inputs'!O65="",IncCCD5,'Scenario Inputs'!O65) -> 0.25 | I25: =IF('Scenario Inputs'!P65="",IncCCD5,'Scenario Inputs'!P65) -> 0.25 | ... N25: =IF('Scenario Inputs'!U65="",IncCCD5,'Scenario Inputs'!U65) -> 0.25
B26: =IF('Scenario Inputs'!I66="",IncCCD6,'Scenario Inputs'!I66) -> 0.5 | C26: =IF('Scenario Inputs'!J66="",IncCCD6,'Scenario Inputs'!J66) -> 0.5 | D26: =IF('Scenario Inputs'!K66="",IncCCD6,'Scenario Inputs'!K66) -> 0.5 | E26: =IF('Scenario Inputs'!L66="",IncCCD6,'Scenario Inputs'!L66) -> 0.5 | F26: =IF('Scenario Inputs'!M66="",IncCCD6,'Scenario Inputs'!M66) -> 0.5 | G26: =IF('Scenario Inputs'!N66="",IncCCD6,'Scenario Inputs'!N66) -> 0.5 | H26: =IF('Scenario Inputs'!O66="",IncCCD6,'Scenario Inputs'!O66) -> 0.5 | I26: =IF('Scenario Inputs'!P66="",IncCCD6,'Scenario Inputs'!P66) -> 0.5 | ... N26: =IF('Scenario Inputs'!U66="",IncCCD6,'Scenario Inputs'!U66) -> 0.5
A27: Change in probability of late presentation | B27: =IF('Scenario Inputs'!I67="",IncLP,'Scenario Inputs'!I67) -> 0.2 | C27: =IF('Scenario Inputs'!J67="",IncLP,'Scenario Inputs'!J67) -> 0.2 | D27: =IF('Scenario Inputs'!K67="",IncLP,'Scenario Inputs'!K67) -> 0.2 | E27: =IF('Scenario Inputs'!L67="",IncLP,'Scenario Inputs'!L67) -> 0.2 | F27: =IF('Scenario Inputs'!M67="",IncLP,'Scenario Inputs'!M67) -> 0.2 | G27: =IF('Scenario Inputs'!N67="",IncLP,'Scenario Inputs'!N67) -> 0.2 | H27: =IF('Scenario Inputs'!O67="",IncLP,'Scenario Inputs'!O67) -> 0.2 | I27: =IF('Scenario Inputs'!P67="",IncLP,'Scenario Inputs'!P67) -> 0.2 | ... N27: =IF('Scenario Inputs'!U67="",IncLP,'Scenario Inputs'!U67) -> 0.2
C29: Rollout year target
B30: Current Value (Default) | C30: 1 | D30: 2 | E30: 3 | F30: 4 | G30: 5 | H30: 6 | I30: 7 | J30: 8 | K30: 9 | L30: 10 | M30: 11 | N30: 12 | O30: 13
A33: Change in probability of pre-emptive live transplant | B33: =IncPElive -> 0.5 | C33: =IF('Scenario Inputs'!I94="",IncPElive,'Scenario Inputs'!I94) -> 0.5 | D33: =IF('Scenario Inputs'!J94="",IncPElive,'Scenario Inputs'!J94) -> 0.5 | E33: =IF('Scenario Inputs'!K94="",IncPElive,'Scenario Inputs'!K94) -> 0.5 | F33: =IF('Scenario Inputs'!L94="",IncPElive,'Scenario Inputs'!L94) -> 0.5 | G33: =IF('Scenario Inputs'!M94="",IncPElive,'Scenario Inputs'!M94) -> 0.5 | H33: =IF('Scenario Inputs'!N94="",IncPElive,'Scenario Inputs'!N94) -> 0.5 | I33: =IF('Scenario Inputs'!O94="",IncPElive,'Scenario Inputs'!O94) -> 0.5 | J33: =IF('Scenario Inputs'!P94="",IncPElive,'Scenario Inputs'!P94) -> 0.5 | ... O33: =IF('Scenario Inputs'!U94="",IncPElive,'Scenario Inputs'!U94) -> 0.5
A34: Change in probability of pre-emptive cadaver transplant | B34: =IncPEcad -> 0 | C34: =IF('Scenario Inputs'!I97="",IncPEcad,'Scenario Inputs'!I97) -> 0 | D34: =IF('Scenario Inputs'!J97="",IncPEcad,'Scenario Inputs'!J97) -> 0 | E34: =IF('Scenario Inputs'!K97="",IncPEcad,'Scenario Inputs'!K97) -> 0 | F34: =IF('Scenario Inputs'!L97="",IncPEcad,'Scenario Inputs'!L97) -> 0 | G34: =IF('Scenario Inputs'!M97="",IncPEcad,'Scenario Inputs'!M97) -> 0 | H34: =IF('Scenario Inputs'!N97="",IncPEcad,'Scenario Inputs'!N97) -> 0 | I34: =IF('Scenario Inputs'!O97="",IncPEcad,'Scenario Inputs'!O97) -> 0 | J34: =IF('Scenario Inputs'!P97="",IncPEcad,'Scenario Inputs'!P97) -> 0 | ... O34: =IF('Scenario Inputs'!U97="",IncPEcad,'Scenario Inputs'!U97) -> 0
A37: Costs
A38: Daily average cost of ICHD | B38: ='Cost Inputs'!K18/365 -> 172.17
A39: Daily average cost of HHD | B39: ='Cost Inputs'!K19/365 -> 140.06
A40: Daily average cost of PD | B40: ='Cost Inputs'!K20/365 -> 107.92
A41: Daily average cost of Living with Tx | B41: ='Cost Inputs'!K21/365 -> 24.67
A43: Arrival Process | C43: 2010 | D43: 2011 | E43: 2012 | F43: 2013 | G43: 2014 | H43: 2015 | I43: 2016 | J43: 2017 | K43: 2018 | L43: 2019 | M43: 2020 | N43: 2021 | O43: 2022 | P43: 2023 | Q43: 2023 | R43: 2024 | S43: 2025 | T43: 2026 | U43: 2027 | V43: 2028 | W43: 2029 | X43: 2030 | Y43: 2031 | Z43: 2032 | AA43: 2033 | AB43: 2034
C44: =daily_rate!A4 -> 0 | D44: =daily_rate!B4 -> 0 | E44: =daily_rate!C4 -> 0 | F44: =daily_rate!D4 -> 0 | G44: =daily_rate!E4 -> 0 | H44: =daily_rate!F4 -> 0 | I44: =daily_rate!G4 -> 0 | J44: =daily_rate!H4 -> 0 | ... AB44: =daily_rate!Z4 -> 0
C45: Validation | P45: Experimentation
A46: Routing Distributions
A48: Suitable for transplant | B48: Inc | C48: Prev | E48: Receives Tx | F48: Inc | G48: Prev | I48: Initially | J48: 1 | K48: 2 | L48: 3 | M48: 4 | N48: 5 | O48: 6 | P48: 7 | Q48: 8 | R48: 9 | S48: 10 | T48: 11 | U48: 12 | V48: 13
A49: 1 | B49: =suitableForTx!B1 -> 0.7 | C49: =suitableForTx!B9 -> 0.7 | E49: 1 | F49: =receivesTx!B1 -> 0.9 | G49: =receivesTx!B9 -> 0.6 | I49: =F49 -> 0.9 | J49: =IF('Scenario Inputs'!I91="",simPy_sheet!$I49,'Scenario Inputs'!I91) -> 0.9 | K49: =IF('Scenario Inputs'!J91="",simPy_sheet!$I49,'Scenario Inputs'!J91) -> 0.9 | L49: =IF('Scenario Inputs'!K91="",simPy_sheet!$I49,'Scenario Inputs'!K91) -> 0.9 | M49: =IF('Scenario Inputs'!L91="",simPy_sheet!$I49,'Scenario Inputs'!L91) -> 0.9 | N49: =IF('Scenario Inputs'!M91="",simPy_sheet!$I49,'Scenario Inputs'!M91) -> 0.9 | O49: =IF('Scenario Inputs'!N91="",simPy_sheet!$I49,'Scenario Inputs'!N91) -> 0.9 | P49: =IF('Scenario Inputs'!O91="",simPy_sheet!$I49,'Scenario Inputs'!O91) -> 0.9 | Q49: =IF('Scenario Inputs'!P91="",simPy_sheet!$I49,'Scenario Inputs'!P91) -> 0.9 | ... V49: =IF('Scenario Inputs'!U91="",simPy_sheet!$I49,'Scenario Inputs'!U91) -> 0.9
A50: 2 | B50: =suitableForTx!B2 -> 0.6 | C50: =suitableForTx!B10 -> 0.6 | E50: 2 | F50: =receivesTx!B2 -> 0.8 | G50: =receivesTx!B10 -> 0.3 | I50: =F50 -> 0.8 | J50: =IF('Scenario Inputs'!I92="",simPy_sheet!$I50,'Scenario Inputs'!I92) -> 0.8 | K50: =IF('Scenario Inputs'!J92="",simPy_sheet!$I50,'Scenario Inputs'!J92) -> 0.8 | L50: =IF('Scenario Inputs'!K92="",simPy_sheet!$I50,'Scenario Inputs'!K92) -> 0.8 | M50: =IF('Scenario Inputs'!L92="",simPy_sheet!$I50,'Scenario Inputs'!L92) -> 0.8 | N50: =IF('Scenario Inputs'!M92="",simPy_sheet!$I50,'Scenario Inputs'!M92) -> 0.8 | O50: =IF('Scenario Inputs'!N92="",simPy_sheet!$I50,'Scenario Inputs'!N92) -> 0.8 | P50: =IF('Scenario Inputs'!O92="",simPy_sheet!$I50,'Scenario Inputs'!O92) -> 0.8 | Q50: =IF('Scenario Inputs'!P92="",simPy_sheet!$I50,'Scenario Inputs'!P92) -> 0.8 | ... V50: =IF('Scenario Inputs'!U92="",simPy_sheet!$I50,'Scenario Inputs'!U92) -> 0.8
...

Sheet Scenario Inputs
C14: Model Parameters
C16: Select Model Parameters | N16: Set Intervention Time Parameters
C18: Select the region and centre of interest. To perform a region level run select "All" on the centre drop down. The default incidence profile is CKD Baseline (from the system dynamics model of disease progression). Other options represent special scenarios run with the CKD model. Baseline is a simple linear projection. | N18: Select the year the intervention is planned to take place. The change is in place from Jan 1st that year. The simulation will run from the start of "run start year" to the end of "run end year". Both are fixed inputs. Note: Dec 31st 2022 is the last observed date in the UKRR data, the model is initialised accordingly.
C20: Region | F20: Fictional Region
C21: Centre | F21: Fictional Centre | N21: Run start year | R21: 2023
C22: Ethnicity | F22: Baseline
C23: Incidence Profile | F23: CKD baseline | N23: Run end year | R23: 2035
N25: Intervention Selection Summary (Of changes made below): | T25: Default Estimate | V25: New Value (Result of user input)
N26: =C49 -> Change in % allocated to HHD | T26: =G49 -> 0.18918919 | V26: =K49 -> 0
N27: =C52 -> Change in % initially allocated to PD | T27: =G52 -> 0.29 | V27: =K52 -> 0
N28: =#REF! -> #REF! | T28: =#REF! -> #REF! | V28: =#REF! -> #REF!
N29: =#REF! -> #REF! | T29: =#REF! -> #REF! | V29: =#REF! -> #REF!
N30: =C91 -> Change to % of patients receiving a transplant | T30: =G91 -> 0.9 | V30: =K91 -> 0
N31: =C94 -> 0 | T31: =G94 -> 0.5 | V31: =K94 -> 0
C33: Centre based growth assumption
C35: Centre based growth assumption: The baseline assumption is that incidence to KRT for a centre grows as a constant proportion of regional growth. This can be edited here to reflect a non-stationary profile of growth for a centre.
G36: Current Value (Default) | I36: Year
I37: 2023 | J37: 2024 | K37: 2025 | L37: 2026 | M37: 2027 | N37: 2028 | O37: 2029 | P37: 2030 | Q37: 2031 | R37: 2032 | S37: 2033 | T37: 2034 | U37: 2035
C38: Centre based growth assumption | G38: 1
G39: Default Incidence: | I39: =daily_rate!N2 -> 0.5 | J39: =daily_rate!O2 -> 0.5 | K39: =daily_rate!P2 -> 0.5 | L39: =daily_rate!Q2 -> 0.5 | M39: =daily_rate!R2 -> 0.5 | N39: =daily_rate!S2 -> 0.5 | O39: =daily_rate!T2 -> 0.5 | P39: =daily_rate!U2 -> 0.5 | ... U39: =daily_rate!Z2 -> 0.5
G40: User Impacted Incidence: | I40: =simPy_sheet!B6 -> 0.5 | J40: =simPy_sheet!C6 -> 0.5 | K40: =simPy_sheet!D6 -> 0.5 | L40: =simPy_sheet!E6 -> 0.5 | M40: =simPy_sheet!F6 -> 0.5 | N40: =simPy_sheet!G6 -> 0.5 | O40: =simPy_sheet!H6 -> 0.5 | P40: =simPy_sheet!I6 -> 0.5 | ... U40: =simPy_sheet!N6 -> 0.5
C41: Interventions
C43: Change in HHD and/or PD allocation | Y43: Reference Values
C45: Change in HHD: Allows a user to change the percentage of people on HHD to a target of x% at the end of each year (to achieve this patients are moved from/to ICHD). Change in PD: Allows a user to change the initial allocation probablity of PD to a target of x% (resulting in shifting the initial ICHD allocation probability up or down). | Y45: The following plots are for reference when setting new scenario values. Values are provided at national (England), regional (Midlands) and centre levels. This should allow a user to pick an optimistic, but realistic scenario value.
G47: Current Value (Default) | I47: Rollout year target percentage
I48: =R21 -> 2023 | J48: =I48+1 -> 2024 | K48: =J48+1 -> 2025 | L48: =K48+1 -> 2026 | M48: =L48+1 -> 2027 | N48: =M48+1 -> 2028 | O48: =N48+1 -> 2029 | P48: =O48+1 -> 2030 | Q48: =P48+1 -> 2031 | ... U48: =T48+1 -> 2035
C49: Change in % allocated to HHD | G49: =simPy_sheet!B257 -> 0.18918919
G50: Default Allocation %: | I50: =IncHHD -> 0.18918919 | J50: =IncHHD -> 0.18918919 | K50: =IncHHD -> 0.18918919 | L50: =IncHHD -> 0.18918919 | M50: =IncHHD -> 0.18918919 | N50: =IncHHD -> 0.18918919 | O50: =IncHHD -> 0.18918919 | P50: =IncHHD -> 0.18918919 | ... U50: =IncHHD -> 0.18918919
G51: User Impacted Allocation %: | I51: =AVERAGE(simPy_sheet!G77:G82) -> 0.18918919 | J51: =AVERAGE(simPy_sheet!J77:J82) -> 0.18918919 | K51: =AVERAGE(simPy_sheet!M77:M82) -> 0.18918919 | L51: =AVERAGE(simPy_sheet!P77:P82) -> 0.18918919 | M51: =AVERAGE(simPy_sheet!S77:S82) -> 0.18918919 | N51: =AVERAGE(simPy_sheet!V77:V82) -> 0.18918919 | O51: =AVERAGE(simPy_sheet!Y77:Y82) -> 0.18918919 | P51: =AVERAGE(simPy_sheet!AB77:AB82) -> 0.18918919 | Q51: =AVERAGE(simPy_sheet!AE77:AE82) -> 0.18918919 | R51: =AVERAGE(simPy_sheet!AH77:AH82) -> 0.18918919 | S51: =AVERAGE(simPy_sheet!AK77:AK82) -> 0.18918919 | T51: =AVERAGE(simPy_sheet!AN77:AN82) -> 0.18918919 | U51: =AVERAGE(simPy_sheet!AQ77:AQ82) -> 0.18918919
C52: Change in % initially allocated to PD | G52: =modAllocation!E1 -> 0.29
G53: Default Allocation %: | I53: =AVERAGE(simPy_sheet!$E$71:$E$76) -> 0.29 | J53: =AVERAGE(simPy_sheet!$E$71:$E$76) -> 0.29 | K53: =AVERAGE(simPy_sheet!$E$71:$E$76) -> 0.29 | L53: =AVERAGE(simPy_sheet!$E$71:$E$76) -> 0.29 | M53: =AVERAGE(simPy_sheet!$E$71:$E$76) -> 0.29 | N53: =AVERAGE(simPy_sheet!$E$71:$E$76) -> 0.29 | O53: =AVERAGE(simPy_sheet!$E$71:$E$76) -> 0.29 | P53: =AVERAGE(simPy_sheet!$E$71:$E$76) -> 0.29 | ... U53: =AVERAGE(simPy_sheet!$E$71:$E$76) -> 0.29
G54: User Impacted Allocation %: | I54: =AVERAGE(simPy_sheet!H71:H76) -> 0.29 | J54: =AVERAGE(simPy_sheet!K71:K76) -> 0.29 | K54: =AVERAGE(simPy_sheet!N71:N76) -> 0.29 | L54: =AVERAGE(simPy_sheet!Q71:Q76) -> 0.29 | M54: =AVERAGE(simPy_sheet!T71:T76) -> 0.29 | N54: =AVERAGE(simPy_sheet!W71:W76) -> 0.29 | O54: =AVERAGE(simPy_sheet!Z71:Z76) -> 0.29 | P54: =AVERAGE(simPy_sheet!AC71:AC76) -> 0.29 | Q54: =AVERAGE(simPy_sheet!AF71:AF76) -> 0.29 | R54: =AVERAGE(simPy_sheet!AI71:AI76) -> 0.29 | S54: =AVERAGE(simPy_sheet!AL71:AL76) -> 0.29 | T54: =AVERAGE(simPy_sheet!AO71:AO76) -> 0.29 | U54: =AVERAGE(simPy_sheet!AR71:AR76) -> 0.29
C55: Diversion to CC and/or reductions in late presentations
C57: Change in divert to conservative care: A relative change in the proportion of all age groups that are diverted to conservative management/care by x%. This is applied equally across all age groups. Change in late presentation: A relative change in the proportion of patients that present to the system late.
G59: Current Value (Default) | I59: Rollout year target percentage
F60: Age group | I60: =R21 -> 2023 | J60: =I60+1 -> 2024 | K60: =J60+1 -> 2025 | L60: =K60+1 -> 2026 | M60: =L60+1 -> 2027 | N60: =M60+1 -> 2028 | O60: =N60+1 -> 2029 | P60: =O60+1 -> 2030 | Q60: =P60+1 -> 2031 | ... U60: =T60+1 -> 2035
C61: Change in probability of diverting to conservative care | F61: 16-35 | G61: =divertToCC!C1 -> 0.1
F62: 36-45 | G62: =divertToCC!C2 -> 0.1
F63: 46-55 | G63: =divertToCC!C3 -> 0.1
F64: 56-65 | G64: =divertToCC!C4 -> 0.1
...

Sheet Cost Inputs
C12: Model Cost Parameters
C14: Average annual costs by treatment pathways per patient | O14: Costing Summary
C16: Default cost inputs are provided here based on costs from the Intercept paper. These can be edited by the user to reflect area specific or updated costing estimates as appropriate. | O16: Default cost inputs are provided here based on costs from the Intercept paper. These can be edited by the user to reflect area specifc or updated costing estimates as appropriate.
G17: Default Model Cost | I17: Adjusted Cost | K17: New Value (Result of user input) | U17: Default Model Cost | W17: New Value (Result of user input) | Z17: HIDE THIS
C18: Annual average cost of ICHD | G18: 62842.05 | K18: =IF(I18="", G18, I18) -> 62842.05 | O18: Treatment Pathway Costs | Q18: Annual average cost of ICHD | U18: 62842.05 | W18: =K18 -> 62842.05 | Z18: =U18 -> 62842.05 | AA18: =W18 -> 62842.05
C19: Annual average cost of HHD | G19: 51121.9 | K19: =IF(I19="", G19, I19) -> 51121.9 | Q19: Annual average cost of HHD | U19: 51121.9 | W19: =K19 -> 51121.9 | Z19: =U19 -> 51121.9 | AA19: =W19 -> 51121.9
C20: Annual average cost of PD | G20: 39390.8 | K20: =IF(I20="", G20, I20) -> 39390.8 | Q20: Annual average cost of PD | U20: 39390.8 | W20: =K20 -> 39390.8 | Z20: =U20 -> 39390.8 | AA20: =W20 -> 39390.8
C21: Annual average cost of Living with Tx | G21: 9004.55 | K21: =IF(I21="", G21, I21) -> 9004.55 | Q21: Annual average cost of Living with Tx | U21: 9004.55 | W21: =K21 -> 9004.55 | Z21: =U21 -> 9004.55 | AA21: =W21 -> 9004.55
J22: ERROR: Cost must be positive above zero. | O22: Intervention Costs | Q22: =E36 -> Intervention 1: KRT intervention | U22: 0 | W22: =V36 -> 0 | Z22: =U22 -> 0 | AA22: =W22 -> 0
Q23: =E37 -> Intervention 2: KRT intervention | U23: 0 | W23: =V37 -> 0 | Z23: =U23 -> 0 | AA23: =W23 -> 0
Q24: =E38 -> Intervention 3: KRT intervention | U24: 0 | W24: =V38 -> 0 | Z24: =U24 -> 0 | AA24: =W24 -> 0
Q25: =E39 -> Intervention 4 | U25: 0 | W25: =V39 -> 0 | Z25: =U25 -> 0 | AA25: =W25 -> 0
Q26: =E40 -> Intervention 5 | U26: 0 | W26: =V40 -> 0 | Z26: =U26 -> 0 | AA26: =W26 -> 0
Q27: All Interventions Total Cost | U27: 0 | W27: =V41 -> 0 | Z27: =U27 -> 0 | AA27: =W27 -> 0
C29: Intervention Costs
E33: Optional: Write in Name of Program / intervention | I33: 2023 | J33: 2024 | K33: 2025 | L33: 2026 | M33: 2027 | N33: 2028 | O33: 2029 | P33: 2030 | Q33: 2031 | R33: 2032 | S33: 2033 | T33: 2034 | U33: 2035 | V33: Total Intervention / Program Cost
E34: Example: CKT/primary care interventions costs | N34: 10000 | O34: 5000 | P34: 5000 | V34: =SUM(I34:U34) -> 20000
E35: Example: KRT/secondary care interventions costs | M35: 50000 | N35: 500 | O35: 500 | P35: 500 | Q35: 10500 | R35: 500 | S35: 500 | T35: 500 | U35: 500 | V35: =SUM(I35:U35) -> 64000
C36: Intervention 1 | E36: Intervention 1: KRT intervention | V36: =SUM(I36:U36) -> 0
C37: Intervention 2 | E37: Intervention 2: KRT intervention | V37: =SUM(I37:U37) -> 0
C38: Intervention 3 | E38: Intervention 3: KRT intervention | V38: =SUM(I38:U38) -> 0
C39: Intervention 4 | E39: Intervention 4 | V39: =SUM(I39:U39) -> 0
C40: Intervention 5 | E40: Intervention 5 | V40: =SUM(I40:U40) -> 0
C41: All interventions (adjusted) | E41: All above interventions | I41: =SUM(I36:I38) -> 0 | J41: =SUM(J36:J38) -> 0 | K41: =SUM(K36:K38) -> 0 | L41: =SUM(L36:L38) -> 0 | M41: =SUM(M36:M38) -> 0 | N41: =SUM(N36:N38) -> 0 | O41: =SUM(O36:O38) -> 0 | P41: =SUM(P36:P38) -> 0 | ... U41: =SUM(U36:U38) -> 0 | V41: =SUM(I41:U41) -> 0
B97: =TxType!B1 -> 0.4
A98: 1 | B98: =TxType!B2 -> 0.25
A99: 2 | B99: =TxType!B3 -> 0.25
A100: 3 | B100: =TxType!B4 -> 0.25
A101: 4 | B101: =TxType!B5 -> 0.15
A102: 5 | B102: =TxType!B6 -> 0.02

Sheet References

Sheet Hide Selection Settings
A1: Region | B1: Unit | C1: Incidence | E1: Unit | F1: Unit population proportions (for incidence profile conversion)
A2: Fictional Region | B2: Fictional Centre | C2: CKD baseline | E2: Fictional Centre | F2: 1
C3: New CKD Scenario

Sheet Prev_Pop_Initialisation
A1: Initialisation | C1: Validation | D1: Experimentation
A2: concare
B3: 1_early: | C3: 0 | D3: 0
B4: 2_early: | C4: 0 | D4: 0
B5: 3_early: | C5: 0 | D5: 0
B6: 4_early: | C6: 0 | D6: 0
B7: 5_early: | C7: 0 | D7: 0
B8: 6_early: | C8: 0 | D8: 0
B9: 1_late: | C9: 0 | D9: 0
B10: 2_late: | C10: 0 | D10: 0
B11: 3_late: | C11: 0 | D11: 0
B12: 4_late: | C12: 0 | D12: 0
B13: 5_late: | C13: 0 | D13: 0
B14: 6_late: | C14: 0 | D14: 0
A16: ichd:
B17: 1_early: | C17: 10 | D17: 20
B18: 2_early: | C18: 10 | D18: 20
B19: 3_early: | C19: 10 | D19: 20
B20: 4_early: | C20: 10 | D20: 20
B21: 5_early: | C21: 10 | D21: 20
B22: 6_early: | C22: 10 | D22: 20
B23: 1_late: | C23: 10 | D23: 20
B24: 2_late: | C24: 10 | D24: 20
B25: 3_late: | C25: 10 | D25: 20
B26: 4_late: | C26: 10 | D26: 20
B27: 5_late: | C27: 10 | D27: 20
B28: 6_late: | C28: 10 | D28: 20
A30: hhd:
B31: 1_early: | C31: 1 | D31: 7
B32: 2_early: | C32: 1 | D32: 7
B33: 3_early: | C33: 1 | D33: 7
B34: 4_early: | C34: 1 | D34: 7
B35: 5_early: | C35: 1 | D35: 7
B36: 6_early: | C36: 1 | D36: 7
B37: 1_late: | C37: 1 | D37: 7
B38: 2_late: | C38: 1 | D38: 7
B39: 3_late: | C39: 1 | D39: 7
B40: 4_late: | C40: 1 | D40: 7
B41: 5_late: | C41: 1 | D41: 7
B42: 6_late: | C42: 1 | D42: 7
...

Sheet age_dist
A1: 1 | B1: 0.05
A2: 2 | B2: 0.07
A3: 3 | B3: 0.12
A4: 4 | B4: 0.2
A5: 5 | B5: 0.25
A6: 6 | B6: =1-SUM(B1:B5) -> 0.31

Sheet referral_dist
A1: Early | B1: 0.8
A2: Late | B2: 0.2

Sheet daily_rate
A1: 2010 | B1: 2011 | C1: 2012 | D1: 2013 | E1: 2014 | F1: 2015 | G1: 2016 | H1: 2017 | I1: 2018 | J1: 2019 | K1: 2020 | L1: 2021 | M1: 2022 | N1: 2023 | O1: 2024 | P1: 2025 | Q1: 2026 | R1: 2027 | S1: 2028 | T1: 2029 | U1: 2030 | V1: 2031 | W1: 2032 | X1: 2033 | Y1: 2034 | Z1: 2035
A2: 0.5 | B2: 0.5 | C2: 0.5 | D2: 0.5 | E2: 0.5 | F2: 0.5 | G2: 0.5 | H2: 0.5 | I2: 0.5 | J2: 0.5 | K2: 0.5 | L2: 0.5 | M2: 0.5 | N2: =IF('Scenario Inputs'!F107>0,'Scenario Inputs'!F107/365,0.5) -> 0.5 | O2: =IF('Scenario Inputs'!G107>0,'Scenario Inputs'!G107/365,0.5) -> 0.5 | P2: =IF('Scenario Inputs'!H107>0,'Scenario Inputs'!H107/365,0.5) -> 0.5 | Q2: =IF('Scenario Inputs'!I107>0,'Scenario Inputs'!I107/365,0.5) -> 0.5 | R2: =IF('Scenario Inputs'!J107>0,'Scenario Inputs'!J107/365,0.5) -> 0.5 | S2: =IF('Scenario Inputs'!K107>0,'Scenario Inputs'!K107/365,0.5) -> 0.5 | T2: =IF('Scenario Inputs'!L107>0,'Scenario Inputs'!L107/365,0.5) -> 0.5 | U2: =IF('Scenario Inputs'!M107>0,'Scenario Inputs'!M107/365,0.5) -> 0.5 | ... Z2: =IF('Scenario Inputs'!R107>0,'Scenario Inputs'!R107/365,0.5) -> 0.5 | XFD2: =VLOOKUP(#REF!,INDIRECT("daily_rate_profiles_all_models!$B$" &#REF!):INDIRECT("daily_rate_profiles_all_models!$AB$" &#REF!),23,TRUE) -> #REF!

Sheet divertToCC
A1: 1 | B1: 1 | C1: 0.1
A2: 2 | B2: 2 | C2: 0.1
A3: 3 | B3: 3 | C3: 0.1
A4: 4 | B4: 4 | C4: 0.1
A5: 5 | B5: 5 | C5: 0.25
A6: 6 | B6: 6 | C6: 0.5

Sheet suitableForTx
A1: 1 | B1: 0.7 | C1: Incident
A2: 2 | B2: 0.6
A3: 3 | B3: 0.5
A4: 4 | B4: 0.4
A5: 5 | B5: 0.2
A6: 6 | B6: 0.05
A9: 1 | B9: 0.7 | C9: Prevalent
A10: 2 | B10: 0.6
A11: 3 | B11: 0.5
A12: 4 | B12: 0.4
A13: 5 | B13: 0.2
A14: 6 | B14: 0.05

Sheet preE_Tx_Cadav
A1: Early | B1: 1 | C1: 0.1
A2: Early | B2: 2 | C2: 0.1
A3: Early | B3: 3 | C3: 0.1
A4: Early | B4: 4 | C4: 0.1
A5: Early | B5: 5 | C5: 0.1
A6: Early | B6: 6 | C6: 0.1
A7: Late | B7: 1 | C7: 0
A8: Late | B8: 2 | C8: 0
A9: Late | B9: 3 | C9: 0
A10: Late | B10: 4 | C10: 0
A11: Late | B11: 5 | C11: 0
A12: Late | B12: 6 | C12: 0

Sheet preE_Tx_Live
A1: Early | B1: 1 | C1: 0.3
A2: Early | B2: 2 | C2: 0.3
A3: Early | B3: 3 | C3: 0.3
A4: Early | B4: 4 | C4: 0.3
A5: Early | B5: 5 | C5: 0.3
A6: Early | B6: 6 | C6: 0.3
A7: Late | B7: 1 | C7: 0
A8: Late | B8: 2 | C8: 0
A9: Late | B9: 3 | C9: 0
A10: Late | B10: 4 | C10: 0
A11: Late | B11: 5 | C11: 0
A12: Late | B12: 6 | C12: 0

Sheet modAllocation
A1: "none" | B1: 1 | C1: 0.69 | D1: 0.02 | E1: 0.29
A2: "none" | B2: 2 | C2: 0.69 | D2: 0.02 | E2: 0.29
A3: "none" | B3: 3 | C3: 0.69 | D3: 0.02 | E3: 0.29
A4: "none" | B4: 4 | C4: 0.69 | D4: 0.02 | E4: 0.29
A5: "none" | B5: 5 | C5: 0.69 | D5: 0.02 | E5: 0.29
A6: "none" | B6: 6 | C6: 0.69 | D6: 0.02 | E6: 0.29
A7: "ichd" | B7: 1 | C7: 0 | D7: 0.2 | E7: 0.8
A8: "ichd" | B8: 1 | C8: 0 | D8: 0.2 | E8: 0.8
A9: "ichd" | B9: 1 | C9: 0 | D9: 0.2 | E9: 0.8
A10: "ichd" | B10: 1 | C10: 0 | D10: 0.2 | E10: 0.8
A11: "ichd" | B11: 2 | C11: 0 | D11: 0.2 | E11: 0.8
A12: "ichd" | B12: 2 | C12: 0 | D12: 0.2 | E12: 0.8
... A24: "pd" | B24: 5 | C24: 0.98 | D24: 0.02 | E24: 0

Sheet TxType
A1: 1 | B1: 0.4
A2: 2 | B2: 0.25
A3: 3 | B3: 0.25
A4: 4 | B4: 0.25
A5: 5 | B5: 0.15
A6: 6 | B6: 0.02
A9: 1 | B9: 0.4
A10: 2 | B10: 0.25
A11: 3 | B11: 0.25
A12: 4 | B12: 0.25
A13: 5 | B13: 0.15
A14: 6 | B14: 0.02

Sheet receivesTx
A1: 1 | B1: 0.9
A2: 2 | B2: 0.8
A3: 3 | B3: 0.6
A4: 4 | B4: 0.5
A5: 5 | B5: 0.5
A6: 6 | B6: 0.1
A9: 1 | B9: 0.6
A10: 2 | B10: 0.3
A11: 3 | B11: 0.3
A12: 4 | B12: 0.3
A13: 5 | B13: 0.15
A14: 6 | B14: 0.1
