Workbook
Name IncCCD1: #REF!
Name IncCCD2: #REF!
Name IncCCD3: #REF!
Name IncCCD4: #REF!
Name IncCCD5: #REF!
Name IncCCD6: #REF!
Name IncHHD: #REF!
Name IncLP: #REF!
Name IncPD: #REF!
Name IncPEcad: #REF!
Name IncPElive: #REF!

Sheet Experiment Summary
D3: Renal Model: Results
D5: This tab info/directions:
D6: To generate results after designing and saving a scenario in the input file you will need to 1. Clone the latest version of the renal capacity model 2. Run the
D7: model using the instructions provided with the model. At the end of the simulation the results will automatically populate this document and produce the results.
D8: Below we display a selection of results.
D10: Model input overview
D12: Region | G12: Fictional Region | O12: Run start year | R12: 2023
D13: Centre | G13: Fictional Centre | O13: Run end year | R13: 2035
D15: Capacity Planning
D17: Total incidence per year broken down by activity (Current Scenario)
D50: Prevalence
D52: Total prevalence at year end (Current Scenario) | O52: Total average prevalence at year end (Data Table)
P54: 2023 | Q54: 2024 | R54: 2025 | S54: 2026 | T54: 2027 | U54: 2028 | V54: 2029 | W54: 2030 | X54: 2031 | Y54: 2032 | Z54: 2033 | AA54: 2034 | AB54: 2035
O55: Current
O56: Total | P56: ='Summary Stats'!D10 -> #REF! | Q56: ='Summary Stats'!E10 -> #REF! | R56: ='Summary Stats'!F10 -> #REF! | S56: ='Summary Stats'!G10 -> #REF! | T56: ='Summary Stats'!H10 -> #REF! | U56: ='Summary Stats'!I10 -> #REF! | V56: ='Summary Stats'!J10 -> #REF! | W56: ='Summary Stats'!K10 -> #REF! | ... AB56: ='Summary Stats'!P10 -> #REF!
O57: ICHD | P57: ='Summary Stats'!D13 -> #REF! | Q57: ='Summary Stats'!E13 -> #REF! | R57: ='Summary Stats'!F13 -> #REF! | S57: ='Summary Stats'!G13 -> #REF! | T57: ='Summary Stats'!H13 -> #REF! | U57: ='Summary Stats'!I13 -> #REF! | V57: ='Summary Stats'!J13 -> #REF! | W57: ='Summary Stats'!K13 -> #REF! | ... AB57: ='Summary Stats'!P13 -> #REF!
O58: HHD | P58: ='Summary Stats'!D14 -> #REF! | Q58: ='Summary Stats'!E14 -> #REF! | R58: ='Summary Stats'!F14 -> #REF! | S58: ='Summary Stats'!G14 -> #REF! | T58: ='Summary Stats'!H14 -> #REF! | U58: ='Summary Stats'!I14 -> #REF! | V58: ='Summary Stats'!J14 -> #REF! | W58: ='Summary Stats'!K14 -> #REF! | ... AB58: ='Summary Stats'!P14 -> #REF!
O59: PD | P59: ='Summary Stats'!D15 -> #REF! | Q59: ='Summary Stats'!E15 -> #REF! | R59: ='Summary Stats'!F15 -> #REF! | S59: ='Summary Stats'!G15 -> #REF! | T59: ='Summary Stats'!H15 -> #REF! | U59: ='Summary Stats'!I15 -> #REF! | V59: ='Summary Stats'!J15 -> #REF! | W59: ='Summary Stats'!K15 -> #REF! | ... AB59: ='Summary Stats'!P15 -> #REF!
O60: Tx Live | P60: ='Summary Stats'!D12 -> #REF! | Q60: ='Summary Stats'!E12 -> #REF! | R60: ='Summary Stats'!F12 -> #REF! | S60: ='Summary Stats'!G12 -> #REF! | T60: ='Summary Stats'!H12 -> #REF! | U60: ='Summary Stats'!I12 -> #REF! | V60: ='Summary Stats'!J12 -> #REF! | W60: ='Summary Stats'!K12 -> #REF! | ... AB60: ='Summary Stats'!P12 -> #REF!
O61: Tx Cadaver | P61: ='Summary Stats'!D11 -> #REF! | Q61: ='Summary Stats'!E11 -> #REF! | R61: ='Summary Stats'!F11 -> #REF! | S61: ='Summary Stats'!G11 -> #REF! | T61: ='Summary Stats'!H11 -> #REF! | U61: ='Summary Stats'!I11 -> #REF! | V61: ='Summary Stats'!J11 -> #REF! | W61: ='Summary Stats'!K11 -> #REF! | ... AB61: ='Summary Stats'!P11 -> #REF!
D69: Total prevalence at year end broken down by activity (Current Scenario)
D101: Costs (Within the KRT system)
D103: Total combined cost of KRT and intervention/s (Current Scenario) | O103: Total combined cost (in millions) of KRT and intervention/s if any (Data Table)
O105: Cost | P105: 2023 | Q105: 2024 | R105: 2025 | S105: 2026 | T105: 2027 | U105: 2028 | V105: 2029 | W105: 2030 | X105: 2031 | Y105: 2032 | Z105: 2033 | AA105: 2034 | AB105: 2035
O106: Current
O107: Total | P107: =Summary_Cost!B2 -> #REF! | Q107: =Summary_Cost!C2 -> #REF! | R107: =Summary_Cost!D2 -> #REF! | S107: =Summary_Cost!E2 -> #REF! | T107: =Summary_Cost!F2 -> #REF! | U107: =Summary_Cost!G2 -> #REF! | V107: =Summary_Cost!H2 -> #REF! | W107: =Summary_Cost!I2 -> #REF! | ... AB107: =Summary_Cost!N2 -> #REF!
O108: ICHD | P108: =Summary_Cost!B3 -> #REF! | Q108: =Summary_Cost!C3 -> #REF! | R108: =Summary_Cost!D3 -> #REF! | S108: =Summary_Cost!E3 -> #REF! | T108: =Summary_Cost!F3 -> #REF! | U108: =Summary_Cost!G3 -> #REF! | V108: =Summary_Cost!H3 -> #REF! | W108: =Summary_Cost!I3 -> #REF! | ... AB108: =Summary_Cost!N3 -> #REF!
O109: HHD | P109: =Summary_Cost!B4 -> #REF! | Q109: =Summary_Cost!C4 -> #REF! | R109: =Summary_Cost!D4 -> #REF! | S109: =Summary_Cost!E4 -> #REF! | T109: =Summary_Cost!F4 -> #REF! | U109: =Summary_Cost!G4 -> #REF! | V109: =Summary_Cost!H4 -> #REF! | W109: =Summary_Cost!I4 -> #REF! | ... AB109: =Summary_Cost!N4 -> #REF!
O110: PD | P110: =Summary_Cost!B5 -> #REF! | Q110: =Summary_Cost!C5 -> #REF! | R110: =Summary_Cost!D5 -> #REF! | S110: =Summary_Cost!E5 -> #REF! | T110: =Summary_Cost!F5 -> #REF! | U110: =Summary_Cost!G5 -> #REF! | V110: =Summary_Cost!H5 -> #REF! | W110: =Summary_Cost!I5 -> #REF! | ... AB110: =Summary_Cost!N5 -> #REF!
O111: Tx | P111: =Summary_Cost!B6 -> #REF! | Q111: =Summary_Cost!C6 -> #REF! | R111: =Summary_Cost!D6 -> #REF! | S111: =Summary_Cost!E6 -> #REF! | T111: =Summary_Cost!F6 -> #REF! | U111: =Summary_Cost!G6 -> #REF! | V111: =Summary_Cost!H6 -> #REF! | W111: =Summary_Cost!I6 -> #REF! | ... AB111: =Summary_Cost!N6 -> #REF!
D119: Total cost of KRT broken down by activity (Default Scenario) | O119: Total cost of KRT broken down by activity (Current Scenario)
D136: Other performance measures
D138: Percentage on home dialysis (Default vs. Current Scenario) | O138: Percentage on home dialysis (Data Table)
P140: 2023 | Q140: 2024 | R140: 2025 | S140: 2026 | T140: 2027 | U140: 2028 | V140: 2029 | W140: 2030 | X140: 2031 | Y140: 2032 | Z140: 2033 | AA140: 2034 | AB140: 2035
O141: Current
O142: Total | P142: 21.079258 | Q142: 22.702523 | R142: 22.999692 | S142: 23.132489 | T142: 23.415098 | U142: 23.373423 | V142: 23.384957 | W142: 23.524307 | X142: 23.557359 | Y142: 23.690862 | Z142: 23.793657 | AA142: 23.716975 | AB142: 23.750287
O143: Default
O144: Total | P144: 18.978105 | Q144: 19.83076 | R144: 20.036286 | S144: 20.552664 | T144: 20.013057 | U144: 20.306761 | V144: 20.685413 | W144: 20.391609 | X144: 20.393045 | Y144: 20.382131 | Z144: 20.436216 | AA144: 20.33701 | AB144: 20.381086
D154: Percentage of transplants that happened pre-emptively (Default vs. Current Scenario) | O154: Percentage of transplants that happened pre-emptively (Data Table)
P156: 2023 | Q156: 2024 | R156: 2025 | S156: 2026 | T156: 2027 | U156: 2028 | V156: 2029 | W156: 2030 | X156: 2031 | Y156: 2032 | Z156: 2033 | AA156: 2034 | AB156: 2035
...

Sheet Summary Stats
A1: Incidence | B1: mean | C1: 0 | D1: 1 | E1: 2 | F1: 3 | G1: 4 | H1: 5 | I1: 6 | J1: 7 | K1: 8 | L1: 9 | M1: 10 | N1: 11 | O1: 12 | P1: 13 | R1: Incidence | S1: standard deviation | T1: 0 | U1: 1 | V1: 2 | W1: 3 | X1: 4 | Y1: 5 | Z1: 6 | AA1: 7 | AB1: 8 | AC1: 9 | AD1: 10 | AE1: 11 | AF1: 12 | AG1: 13 | AI1: Incidence | AJ1: CI width | AK1: 0 | AL1: 1 | AM1: 2 | AN1: 3 | AO1: 4 | AP1: 5 | AQ1: 6 | AR1: 7 | AS1: 8 | AT1: 9 | AU1: 10 | AV1: 11 | AW1: 12 | AX1: 13
A2: Total | B2: Validation | C2: =SUM(C3:C7) -> #REF! | D2: =SUM(D3:D7) -> #REF! | E2: =SUM(E3:E7) -> #REF! | F2: =SUM(F3:F7) -> #REF! | G2: =SUM(G3:G7) -> #REF! | H2: =SUM(H3:H7) -> #REF! | I2: =SUM(I3:I7) -> #REF! | J2: =SUM(J3:J7) -> #REF! | ... P2: =SUM(P3:P7) -> #REF! | R2: Total | S2: Validation | AI2: Total | AJ2: Validation
A3: Cadaver | B3: Validation | C3: =AVERAGE(OFFSET(incidence_cadaver!B:B,1,0,COUNTA(incidence_cadaver!B:B)-1)) -> #REF! | D3: =AVERAGE(OFFSET(incidence_cadaver!C:C,1,0,COUNTA(incidence_cadaver!C:C)-1)) -> #REF! | E3: =AVERAGE(OFFSET(incidence_cadaver!D:D,1,0,COUNTA(incidence_cadaver!D:D)-1)) -> #REF! | F3: =AVERAGE(OFFSET(incidence_cadaver!E:E,1,0,COUNTA(incidence_cadaver!E:E)-1)) -> #REF! | G3: =AVERAGE(OFFSET(incidence_cadaver!F:F,1,0,COUNTA(incidence_cadaver!F:F)-1)) -> #REF! | H3: =AVERAGE(OFFSET(incidence_cadaver!G:G,1,0,COUNTA(incidence_cadaver!G:G)-1)) -> #REF! | I3: =AVERAGE(OFFSET(incidence_cadaver!H:H,1,0,COUNTA(incidence_cadaver!H:H)-1)) -> #REF! | J3: =AVERAGE(OFFSET(incidence_cadaver!I:I,1,0,COUNTA(incidence_cadaver!I:I)-1)) -> #REF! | K3: =AVERAGE(OFFSET(incidence_cadaver!J:J,1,0,COUNTA(incidence_cadaver!J:J)-1)) -> #REF! | L3: =AVERAGE(OFFSET(incidence_cadaver!K:K,1,0,COUNTA(incidence_cadaver!K:K)-1)) -> #REF! | M3: =AVERAGE(OFFSET(incidence_cadaver!L:L,1,0,COUNTA(incidence_cadaver!L:L)-1)) -> #REF! | N3: =AVERAGE(OFFSET(incidence_cadaver!M:M,1,0,COUNTA(incidence_cadaver!M:M)-1)) -> #REF! | O3: =AVERAGE(OFFSET(incidence_cadaver!N:N,1,0,COUNTA(incidence_cadaver!N:N)-1)) -> #REF! | P3: =AVERAGE(OFFSET(incidence_cadaver!O:O,1,0,COUNTA(incidence_cadaver!O:O)-1)) -> #REF! | R3: Cadaver | S3: Validation | T3: =_xlfn.STDEV.S(OFFSET(incidence_cadaver!B:B,1,0,COUNTA(incidence_cadaver!B:B)-1)) -> #REF! | U3: =_xlfn.STDEV.S(OFFSET(incidence_cadaver!C:C,1,0,COUNTA(incidence_cadaver!C:C)-1)) -> #REF! | V3: =_xlfn.STDEV.S(OFFSET(incidence_cadaver!D:D,1,0,COUNTA(incidence_cadaver!D:D)-1)) -> #REF! | W3: =_xlfn.STDEV.S(OFFSET(incidence_cadaver!E:E,1,0,COUNTA(incidence_cadaver!E:E)-1)) -> #REF! | X3: =_xlfn.STDEV.S(OFFSET(incidence_cadaver!F:F,1,0,COUNTA(incidence_cadaver!F:F)-1)) -> #REF! | Y3: =_xlfn.STDEV.S(OFFSET(incidence_cadaver!G:G,1,0,COUNTA(incidence_cadaver!G:G)-1)) -> #REF! | Z3: =_xlfn.STDEV.S(OFFSET(incidence_cadaver!H:H,1,0,COUNTA(incidence_cadaver!H:H)-1)) -> #REF! | AA3: =_xlfn.STDEV.S(OFFSET(incidence_cadaver!I:I,1,0,COUNTA(incidence_cadaver!I:I)-1)) -> #REF! | AB3: =_xlfn.STDEV.S(OFFSET(incidence_cadaver!J:J,1,0,COUNTA(incidence_cadaver!J:J)-1)) -> #REF! | AC3: =_xlfn.STDEV.S(OFFSET(incidence_cadaver!K:K,1,0,COUNTA(incidence_cadaver!K:K)-1)) -> #REF! | AD3: =_xlfn.STDEV.S(OFFSET(incidence_cadaver!L:L,1,0,COUNTA(incidence_cadaver!L:L)-1)) -> #REF! | AE3: =_xlfn.STDEV.S(OFFSET(incidence_cadaver!M:M,1,0,COUNTA(incidence_cadaver!M:M)-1)) -> #REF! | AF3: =_xlfn.STDEV.S(OFFSET(incidence_cadaver!N:N,1,0,COUNTA(incidence_cadaver!N:N)-1)) -> #REF! | AG3: =_xlfn.STDEV.S(OFFSET(incidence_cadaver!O:O,1,0,COUNTA(incidence_cadaver!O:O)-1)) -> #REF! | AI3: Cadaver | AJ3: Validation | AK3: 0 | AL3: =1.96*U3/SQRT(COUNT(incidence_cadaver!B:B)-1) -> #REF! | AM3: =1.96*V3/SQRT(COUNT(incidence_cadaver!C:C)-1) -> #REF! | AN3: =1.96*W3/SQRT(COUNT(incidence_cadaver!D:D)-1) -> #REF! | AO3: =1.96*X3/SQRT(COUNT(incidence_cadaver!E:E)-1) -> #REF! | AP3: =1.96*Y3/SQRT(COUNT(incidence_cadaver!F:F)-1) -> #REF! | AQ3: =1.96*Z3/SQRT(COUNT(incidence_cadaver!G:G)-1) -> #REF! | AR3: =1.96*AA3/SQRT(COUNT(incidence_cadaver!H:H)-1) -> #REF! | AS3: =1.96*AB3/SQRT(COUNT(incidence_cadaver!I:I)-1) -> #REF! | AT3: =1.96*AC3/SQRT(COUNT(incidence_cadaver!J:J)-1) -> #REF! | AU3: =1.96*AD3/SQRT(COUNT(incidence_cadaver!K:K)-1) -> #REF! | AV3: =1.96*AE3/SQRT(COUNT(incidence_cadaver!L:L)-1) -> #REF! | AW3: =1.96*AF3/SQRT(COUNT(incidence_cadaver!M:M)-1) -> #REF! | AX3: =1.96*AG3/SQRT(COUNT(incidence_cadaver!N:N)-1) -> #REF!
A4: Live | B4: Validation | C4: =AVERAGE(OFFSET(incidence_live!B:B,1,0,COUNTA(incidence_live!B:B)-1)) -> #REF! | D4: =AVERAGE(OFFSET(incidence_live!C:C,1,0,COUNTA(incidence_live!C:C)-1)) -> #REF! | E4: =AVERAGE(OFFSET(incidence_live!D:D,1,0,COUNTA(incidence_live!D:D)-1)) -> #REF! | F4: =AVERAGE(OFFSET(incidence_live!E:E,1,0,COUNTA(incidence_live!E:E)-1)) -> #REF! | G4: =AVERAGE(OFFSET(incidence_live!F:F,1,0,COUNTA(incidence_live!F:F)-1)) -> #REF! | H4: =AVERAGE(OFFSET(incidence_live!G:G,1,0,COUNTA(incidence_live!G:G)-1)) -> #REF! | I4: =AVERAGE(OFFSET(incidence_live!H:H,1,0,COUNTA(incidence_live!H:H)-1)) -> #REF! | J4: =AVERAGE(OFFSET(incidence_live!I:I,1,0,COUNTA(incidence_live!I:I)-1)) -> #REF! | K4: =AVERAGE(OFFSET(incidence_live!J:J,1,0,COUNTA(incidence_live!J:J)-1)) -> #REF! | L4: =AVERAGE(OFFSET(incidence_live!K:K,1,0,COUNTA(incidence_live!K:K)-1)) -> #REF! | M4: =AVERAGE(OFFSET(incidence_live!L:L,1,0,COUNTA(incidence_live!L:L)-1)) -> #REF! | N4: =AVERAGE(OFFSET(incidence_live!M:M,1,0,COUNTA(incidence_live!M:M)-1)) -> #REF! | O4: =AVERAGE(OFFSET(incidence_live!N:N,1,0,COUNTA(incidence_live!N:N)-1)) -> #REF! | P4: =AVERAGE(OFFSET(incidence_live!O:O,1,0,COUNTA(incidence_live!O:O)-1)) -> #REF! | R4: Live | S4: Validation | T4: =_xlfn.STDEV.S(OFFSET(incidence_live!B:B,1,0,COUNTA(incidence_live!B:B)-1)) -> #REF! | U4: =_xlfn.STDEV.S(OFFSET(incidence_live!C:C,1,0,COUNTA(incidence_live!C:C)-1)) -> #REF! | V4: =_xlfn.STDEV.S(OFFSET(incidence_live!D:D,1,0,COUNTA(incidence_live!D:D)-1)) -> #REF! | W4: =_xlfn.STDEV.S(OFFSET(incidence_live!E:E,1,0,COUNTA(incidence_live!E:E)-1)) -> #REF! | X4: =_xlfn.STDEV.S(OFFSET(incidence_live!F:F,1,0,COUNTA(incidence_live!F:F)-1)) -> #REF! | Y4: =_xlfn.STDEV.S(OFFSET(incidence_live!G:G,1,0,COUNTA(incidence_live!G:G)-1)) -> #REF! | Z4: =_xlfn.STDEV.S(OFFSET(incidence_live!H:H,1,0,COUNTA(incidence_live!H:H)-1)) -> #REF! | AA4: =_xlfn.STDEV.S(OFFSET(incidence_live!I:I,1,0,COUNTA(incidence_live!I:I)-1)) -> #REF! | AB4: =_xlfn.STDEV.S(OFFSET(incidence_live!J:J,1,0,COUNTA(incidence_live!J:J)-1)) -> #REF! | AC4: =_xlfn.STDEV.S(OFFSET(incidence_live!K:K,1,0,COUNTA(incidence_live!K:K)-1)) -> #REF! | AD4: =_xlfn.STDEV.S(OFFSET(incidence_live!L:L,1,0,COUNTA(incidence_live!L:L)-1)) -> #REF! | AE4: =_xlfn.STDEV.S(OFFSET(incidence_live!M:M,1,0,COUNTA(incidence_live!M:M)-1)) -> #REF! | AF4: =_xlfn.STDEV.S(OFFSET(incidence_live!N:N,1,0,COUNTA(incidence_live!N:N)-1)) -> #REF! | AG4: =_xlfn.STDEV.S(OFFSET(incidence_live!O:O,1,0,COUNTA(incidence_live!O:O)-1)) -> #REF! | AI4: Live | AJ4: Validation | AK4: 0 | AL4: =1.96*U4/SQRT(COUNT(incidence_cadaver!B:B)-1) -> #REF! | AM4: =1.96*V4/SQRT(COUNT(incidence_cadaver!C:C)-1) -> #REF! | AN4: =1.96*W4/SQRT(COUNT(incidence_cadaver!D:D)-1) -> #REF! | AO4: =1.96*X4/SQRT(COUNT(incidence_cadaver!E:E)-1) -> #REF! | AP4: =1.96*Y4/SQRT(COUNT(incidence_cadaver!F:F)-1) -> #REF! | AQ4: =1.96*Z4/SQRT(COUNT(incidence_cadaver!G:G)-1) -> #REF! | AR4: =1.96*AA4/SQRT(COUNT(incidence_cadaver!H:H)-1) -> #REF! | AS4: =1.96*AB4/SQRT(COUNT(incidence_cadaver!I:I)-1) -> #REF! | AT4: =1.96*AC4/SQRT(COUNT(incidence_cadaver!J:J)-1) -> #REF! | AU4: =1.96*AD4/SQRT(COUNT(incidence_cadaver!K:K)-1) -> #REF! | AV4: =1.96*AE4/SQRT(COUNT(incidence_cadaver!L:L)-1) -> #REF! | AW4: =1.96*AF4/SQRT(COUNT(incidence_cadaver!M:M)-1) -> #REF! | AX4: =1.96*AG4/SQRT(COUNT(incidence_cadaver!N:N)-1) -> #REF!
A5: ICHD | B5: Validation | C5: =AVERAGE(OFFSET(incidence_ichd!B:B,1,0,COUNTA(incidence_ichd!B:B)-1)) -> #REF! | D5: =AVERAGE(OFFSET(incidence_ichd!C:C,1,0,COUNTA(incidence_ichd!C:C)-1)) -> #REF! | E5: =AVERAGE(OFFSET(incidence_ichd!D:D,1,0,COUNTA(incidence_ichd!D:D)-1)) -> #REF! | F5: =AVERAGE(OFFSET(incidence_ichd!E:E,1,0,COUNTA(incidence_ichd!E:E)-1)) -> #REF! | G5: =AVERAGE(OFFSET(incidence_ichd!F:F,1,0,COUNTA(incidence_ichd!F:F)-1)) -> #REF! | H5: =AVERAGE(OFFSET(incidence_ichd!G:G,1,0,COUNTA(incidence_ichd!G:G)-1)) -> #REF! | I5: =AVERAGE(OFFSET(incidence_ichd!H:H,1,0,COUNTA(incidence_ichd!H:H)-1)) -> #REF! | J5: =AVERAGE(OFFSET(incidence_ichd!I:I,1,0,COUNTA(incidence_ichd!I:I)-1)) -> #REF! | K5: =AVERAGE(OFFSET(incidence_ichd!J:J,1,0,COUNTA(incidence_ichd!J:J)-1)) -> #REF! | L5: =AVERAGE(OFFSET(incidence_ichd!K:K,1,0,COUNTA(incidence_ichd!K:K)-1)) -> #REF! | M5: =AVERAGE(OFFSET(incidence_ichd!L:L,1,0,COUNTA(incidence_ichd!L:L)-1)) -> #REF! | N5: =AVERAGE(OFFSET(incidence_ichd!M:M,1,0,COUNTA(incidence_ichd!M:M)-1)) -> #REF! | O5: =AVERAGE(OFFSET(incidence_ichd!N:N,1,0,COUNTA(incidence_ichd!N:N)-1)) -> #REF! | P5: =AVERAGE(OFFSET(incidence_ichd!O:O,1,0,COUNTA(incidence_ichd!O:O)-1)) -> #REF! | R5: ICHD | S5: Validation | T5: =_xlfn.STDEV.S(OFFSET(incidence_live!B:B,1,0,COUNTA(incidence_live!B:B)-1)) -> #REF! | U5: =_xlfn.STDEV.S(OFFSET(incidence_live!C:C,1,0,COUNTA(incidence_live!C:C)-1)) -> #REF! | V5: =_xlfn.STDEV.S(OFFSET(incidence_live!D:D,1,0,COUNTA(incidence_live!D:D)-1)) -> #REF! | W5: =_xlfn.STDEV.S(OFFSET(incidence_live!E:E,1,0,COUNTA(incidence_live!E:E)-1)) -> #REF! | X5: =_xlfn.STDEV.S(OFFSET(incidence_live!F:F,1,0,COUNTA(incidence_live!F:F)-1)) -> #REF! | Y5: =_xlfn.STDEV.S(OFFSET(incidence_live!G:G,1,0,COUNTA(incidence_live!G:G)-1)) -> #REF! | Z5: =_xlfn.STDEV.S(OFFSET(incidence_live!H:H,1,0,COUNTA(incidence_live!H:H)-1)) -> #REF! | AA5: =_xlfn.STDEV.S(OFFSET(incidence_live!I:I,1,0,COUNTA(incidence_live!I:I)-1)) -> #REF! | AB5: =_xlfn.STDEV.S(OFFSET(incidence_live!J:J,1,0,COUNTA(incidence_live!J:J)-1)) -> #REF! | AC5: =_xlfn.STDEV.S(OFFSET(incidence_live!K:K,1,0,COUNTA(incidence_live!K:K)-1)) -> #REF! | AD5: =_xlfn.STDEV.S(OFFSET(incidence_live!L:L,1,0,COUNTA(incidence_live!L:L)-1)) -> #REF! | AE5: =_xlfn.STDEV.S(OFFSET(incidence_live!M:M,1,0,COUNTA(incidence_live!M:M)-1)) -> #REF! | AF5: =_xlfn.STDEV.S(OFFSET(incidence_live!N:N,1,0,COUNTA(incidence_live!N:N)-1)) -> #REF! | AG5: =_xlfn.STDEV.S(OFFSET(incidence_live!O:O,1,0,COUNTA(incidence_live!O:O)-1)) -> #REF! | AI5: ICHD | AJ5: Validation | AK5: 0 | AL5: =1.96*U5/SQRT(COUNT(incidence_cadaver!B:B)-1) -> #REF! | AM5: =1.96*V5/SQRT(COUNT(incidence_cadaver!C:C)-1) -> #REF! | AN5: =1.96*W5/SQRT(COUNT(incidence_cadaver!D:D)-1) -> #REF! | AO5: =1.96*X5/SQRT(COUNT(incidence_cadaver!E:E)-1) -> #REF! | AP5: =1.96*Y5/SQRT(COUNT(incidence_cadaver!F:F)-1) -> #REF! | AQ5: =1.96*Z5/SQRT(COUNT(incidence_cadaver!G:G)-1) -> #REF! | AR5: =1.96*AA5/SQRT(COUNT(incidence_cadaver!H:H)-1) -> #REF! | AS5: =1.96*AB5/SQRT(COUNT(incidence_cadaver!I:I)-1) -> #REF! | AT5: =1.96*AC5/SQRT(COUNT(incidence_cadaver!J:J)-1) -> #REF! | AU5: =1.96*AD5/SQRT(COUNT(incidence_cadaver!K:K)-1) -> #REF! | AV5: =1.96*AE5/SQRT(COUNT(incidence_cadaver!L:L)-1) -> #REF! | AW5: =1.96*AF5/SQRT(COUNT(incidence_cadaver!M:M)-1) -> #REF! | AX5: =1.96*AG5/SQRT(COUNT(incidence_cadaver!N:N)-1) -> #REF!
A6: HHD | B6: Validation | C6: =AVERAGE(OFFSET(incidence_hhd!B:B,1,0,COUNTA(incidence_hhd!B:B)-1)) -> #REF! | D6: =AVERAGE(OFFSET(incidence_hhd!C:C,1,0,COUNTA(incidence_hhd!C:C)-1)) -> #REF! | E6: =AVERAGE(OFFSET(incidence_hhd!D:D,1,0,COUNTA(incidence_hhd!D:D)-1)) -> #REF! | F6: =AVERAGE(OFFSET(incidence_hhd!E:E,1,0,COUNTA(incidence_hhd!E:E)-1)) -> #REF! | G6: =AVERAGE(OFFSET(incidence_hhd!F:F,1,0,COUNTA(incidence_hhd!F:F)-1)) -> #REF! | H6: =AVERAGE(OFFSET(incidence_hhd!G:G,1,0,COUNTA(incidence_hhd!G:G)-1)) -> #REF! | I6: =AVERAGE(OFFSET(incidence_hhd!H:H,1,0,COUNTA(incidence_hhd!H:H)-1)) -> #REF! | J6: =AVERAGE(OFFSET(incidence_hhd!I:I,1,0,COUNTA(incidence_hhd!I:I)-1)) -> #REF! | K6: =AVERAGE(OFFSET(incidence_hhd!J:J,1,0,COUNTA(incidence_hhd!J:J)-1)) -> #REF! | L6: =AVERAGE(OFFSET(incidence_hhd!K:K,1,0,COUNTA(incidence_hhd!K:K)-1)) -> #REF! | M6: =AVERAGE(OFFSET(incidence_hhd!L:L,1,0,COUNTA(incidence_hhd!L:L)-1)) -> #REF! | N6: =AVERAGE(OFFSET(incidence_hhd!M:M,1,0,COUNTA(incidence_hhd!M:M)-1)) -> #REF! | O6: =AVERAGE(OFFSET(incidence_hhd!N:N,1,0,COUNTA(incidence_hhd!N:N)-1)) -> #REF! | P6: =AVERAGE(OFFSET(incidence_hhd!O:O,1,0,COUNTA(incidence_hhd!O:O)-1)) -> #REF! | R6: HHD | S6: Validation | T6: =_xlfn.STDEV.S(OFFSET(incidence_ichd!B:B,1,0,COUNTA(incidence_ichd!B:B)-1)) -> #REF! | U6: =_xlfn.STDEV.S(OFFSET(incidence_ichd!C:C,1,0,COUNTA(incidence_ichd!C:C)-1)) -> #REF! | V6: =_xlfn.STDEV.S(OFFSET(incidence_ichd!D:D,1,0,COUNTA(incidence_ichd!D:D)-1)) -> #REF! | W6: =_xlfn.STDEV.S(OFFSET(incidence_ichd!E:E,1,0,COUNTA(incidence_ichd!E:E)-1)) -> #REF! | X6: =_xlfn.STDEV.S(OFFSET(incidence_ichd!F:F,1,0,COUNTA(incidence_ichd!F:F)-1)) -> #REF! | Y6: =_xlfn.STDEV.S(OFFSET(incidence_ichd!G:G,1,0,COUNTA(incidence_ichd!G:G)-1)) -> #REF! | Z6: =_xlfn.STDEV.S(OFFSET(incidence_ichd!H:H,1,0,COUNTA(incidence_ichd!H:H)-1)) -> #REF! | AA6: =_xlfn.STDEV.S(OFFSET(incidence_ichd!I:I,1,0,COUNTA(incidence_ichd!I:I)-1)) -> #REF! | AB6: =_xlfn.STDEV.S(OFFSET(incidence_ichd!J:J,1,0,COUNTA(incidence_ichd!J:J)-1)) -> #REF! | AC6: =_xlfn.STDEV.S(OFFSET(incidence_ichd!K:K,1,0,COUNTA(incidence_ichd!K:K)-1)) -> #REF! | AD6: =_xlfn.STDEV.S(OFFSET(incidence_ichd!L:L,1,0,COUNTA(incidence_ichd!L:L)-1)) -> #REF! | AE6: =_xlfn.STDEV.S(OFFSET(incidence_ichd!M:M,1,0,COUNTA(incidence_ichd!M:M)-1)) -> #REF! | AF6: =_xlfn.STDEV.S(OFFSET(incidence_ichd!N:N,1,0,COUNTA(incidence_ichd!N:N)-1)) -> #REF! | AG6: =_xlfn.STDEV.S(OFFSET(incidence_ichd!O:O,1,0,COUNTA(incidence_ichd!O:O)-1)) -> #REF! | AI6: HHD | AJ6: Validation | AK6: 0 | AL6: =1.96*U6/SQRT(COUNT(incidence_cadaver!B:B)-1) -> #REF! | AM6: =1.96*V6/SQRT(COUNT(incidence_cadaver!C:C)-1) -> #REF! | AN6: =1.96*W6/SQRT(COUNT(incidence_cadaver!D:D)-1) -> #REF! | AO6: =1.96*X6/SQRT(COUNT(incidence_cadaver!E:E)-1) -> #REF! | AP6: =1.96*Y6/SQRT(COUNT(incidence_cadaver!F:F)-1) -> #REF! | AQ6: =1.96*Z6/SQRT(COUNT(incidence_cadaver!G:G)-1) -> #REF! | AR6: =1.96*AA6/SQRT(COUNT(incidence_cadaver!H:H)-1) -> #REF! | AS6: =1.96*AB6/SQRT(COUNT(incidence_cadaver!I:I)-1) -> #REF! | AT6: =1.96*AC6/SQRT(COUNT(incidence_cadaver!J:J)-1) -> #REF! | AU6: =1.96*AD6/SQRT(COUNT(incidence_cadaver!K:K)-1) -> #REF! | AV6: =1.96*AE6/SQRT(COUNT(incidence_cadaver!L:L)-1) -> #REF! | AW6: =1.96*AF6/SQRT(COUNT(incidence_cadaver!M:M)-1) -> #REF! | AX6: =1.96*AG6/SQRT(COUNT(incidence_cadaver!N:N)-1) -> #REF!
A7: PD | B7: Validation | C7: =AVERAGE(OFFSET(incidence_pd!B:B,1,0,COUNTA(incidence_pd!B:B)-1)) -> #REF! | D7: =AVERAGE(OFFSET(incidence_pd!C:C,1,0,COUNTA(incidence_pd!C:C)-1)) -> #REF! | E7: =AVERAGE(OFFSET(incidence_pd!D:D,1,0,COUNTA(incidence_pd!D:D)-1)) -> #REF! | F7: =AVERAGE(OFFSET(incidence_pd!E:E,1,0,COUNTA(incidence_pd!E:E)-1)) -> #REF! | G7: =AVERAGE(OFFSET(incidence_pd!F:F,1,0,COUNTA(incidence_pd!F:F)-1)) -> #REF! | H7: =AVERAGE(OFFSET(incidence_pd!G:G,1,0,COUNTA(incidence_pd!G:G)-1)) -> #REF! | I7: =AVERAGE(OFFSET(incidence_pd!H:H,1,0,COUNTA(incidence_pd!H:H)-1)) -> #REF! | J7: =AVERAGE(OFFSET(incidence_pd!I:I,1,0,COUNTA(incidence_pd!I:I)-1)) -> #REF! | K7: =AVERAGE(OFFSET(incidence_pd!J:J,1,0,COUNTA(incidence_pd!J:J)-1)) -> #REF! | L7: =AVERAGE(OFFSET(incidence_pd!K:K,1,0,COUNTA(incidence_pd!K:K)-1)) -> #REF! | M7: =AVERAGE(OFFSET(incidence_pd!L:L,1,0,COUNTA(incidence_pd!L:L)-1)) -> #REF! | N7: =AVERAGE(OFFSET(incidence_pd!M:M,1,0,COUNTA(incidence_pd!M:M)-1)) -> #REF! | O7: =AVERAGE(OFFSET(incidence_pd!N:N,1,0,COUNTA(incidence_pd!N:N)-1)) -> #REF! | P7: =AVERAGE(OFFSET(incidence_pd!O:O,1,0,COUNTA(incidence_pd!O:O)-1)) -> #REF! | R7: PD | S7: Validation | T7: =_xlfn.STDEV.S(OFFSET(incidence_pd!B:B,1,0,COUNTA(incidence_pd!B:B)-1)) -> #REF! | U7: =_xlfn.STDEV.S(OFFSET(incidence_pd!C:C,1,0,COUNTA(incidence_pd!C:C)-1)) -> #REF! | V7: =_xlfn.STDEV.S(OFFSET(incidence_pd!D:D,1,0,COUNTA(incidence_pd!D:D)-1)) -> #REF! | W7: =_xlfn.STDEV.S(OFFSET(incidence_pd!E:E,1,0,COUNTA(incidence_pd!E:E)-1)) -> #REF! | X7: =_xlfn.STDEV.S(OFFSET(incidence_pd!F:F,1,0,COUNTA(incidence_pd!F:F)-1)) -> #REF! | Y7: =_xlfn.STDEV.S(OFFSET(incidence_pd!G:G,1,0,COUNTA(incidence_pd!G:G)-1)) -> #REF! | Z7: =_xlfn.STDEV.S(OFFSET(incidence_pd!H:H,1,0,COUNTA(incidence_pd!H:H)-1)) -> #REF! | AA7: =_xlfn.STDEV.S(OFFSET(incidence_pd!I:I,1,0,COUNTA(incidence_pd!I:I)-1)) -> #REF! | AB7: =_xlfn.STDEV.S(OFFSET(incidence_pd!J:J,1,0,COUNTA(incidence_pd!J:J)-1)) -> #REF! | AC7: =_xlfn.STDEV.S(OFFSET(incidence_pd!K:K,1,0,COUNTA(incidence_pd!K:K)-1)) -> #REF! | AD7: =_xlfn.STDEV.S(OFFSET(incidence_pd!L:L,1,0,COUNTA(incidence_pd!L:L)-1)) -> #REF! | AE7: =_xlfn.STDEV.S(OFFSET(incidence_pd!M:M,1,0,COUNTA(incidence_pd!M:M)-1)) -> #REF! | AF7: =_xlfn.STDEV.S(OFFSET(incidence_pd!N:N,1,0,COUNTA(incidence_pd!N:N)-1)) -> #REF! | AG7: =_xlfn.STDEV.S(OFFSET(incidence_pd!O:O,1,0,COUNTA(incidence_pd!O:O)-1)) -> #REF! | AI7: PD | AJ7: Validation | AK7: 0 | AL7: =1.96*U7/SQRT(COUNT(incidence_cadaver!B:B)-1) -> #REF! | AM7: =1.96*V7/SQRT(COUNT(incidence_cadaver!C:C)-1) -> #REF! | AN7: =1.96*W7/SQRT(COUNT(incidence_cadaver!D:D)-1) -> #REF! | AO7: =1.96*X7/SQRT(COUNT(incidence_cadaver!E:E)-1) -> #REF! | AP7: =1.96*Y7/SQRT(COUNT(incidence_cadaver!F:F)-1) -> #REF! | AQ7: =1.96*Z7/SQRT(COUNT(incidence_cadaver!G:G)-1) -> #REF! | AR7: =1.96*AA7/SQRT(COUNT(incidence_cadaver!H:H)-1) -> #REF! | AS7: =1.96*AB7/SQRT(COUNT(incidence_cadaver!I:I)-1) -> #REF! | AT7: =1.96*AC7/SQRT(COUNT(incidence_cadaver!J:J)-1) -> #REF! | AU7: =1.96*AD7/SQRT(COUNT(incidence_cadaver!K:K)-1) -> #REF! | AV7: =1.96*AE7/SQRT(COUNT(incidence_cadaver!L:L)-1) -> #REF! | AW7: =1.96*AF7/SQRT(COUNT(incidence_cadaver!M:M)-1) -> #REF! | AX7: =1.96*AG7/SQRT(COUNT(incidence_cadaver!N:N)-1) -> #REF!
A9: Prevalence | R9: Prevalence | AI9: Prevalence
A10: Total | B10: Validation | C10: =SUM(C11:C15) -> #REF! | D10: =SUM(D11:D15) -> #REF! | E10: =SUM(E11:E15) -> #REF! | F10: =SUM(F11:F15) -> #REF! | G10: =SUM(G11:G15) -> #REF! | H10: =SUM(H11:H15) -> #REF! | I10: =SUM(I11:I15) -> #REF! | J10: =SUM(J11:J15) -> #REF! | ... P10: =SUM(P11:P15) -> #REF! | R10: Total | S10: Validation | T10: =_xlfn.STDEV.S(OFFSET(prevalence_total!B:B,1,0,COUNTA(prevalence_total!B:B)-1)) -> 0 | U10: =_xlfn.STDEV.S(OFFSET(prevalence_total!C:C,1,0,COUNTA(prevalence_total!C:C)-1)) -> 0 | V10: =_xlfn.STDEV.S(OFFSET(prevalence_total!D:D,1,0,COUNTA(prevalence_total!D:D)-1)) -> 0 | W10: =_xlfn.STDEV.S(OFFSET(prevalence_total!E:E,1,0,COUNTA(prevalence_total!E:E)-1)) -> 0 | X10: =_xlfn.STDEV.S(OFFSET(prevalence_total!F:F,1,0,COUNTA(prevalence_total!F:F)-1)) -> 0 | Y10: =_xlfn.STDEV.S(OFFSET(prevalence_total!G:G,1,0,COUNTA(prevalence_total!G:G)-1)) -> 0 | Z10: =_xlfn.STDEV.S(OFFSET(prevalence_total!H:H,1,0,COUNTA(prevalence_total!H:H)-1)) -> 0 | AA10: =_xlfn.STDEV.S(OFFSET(prevalence_total!I:I,1,0,COUNTA(prevalence_total!I:I)-1)) -> 0 | AB10: =_xlfn.STDEV.S(OFFSET(prevalence_total!J:J,1,0,COUNTA(prevalence_total!J:J)-1)) -> 0 | AC10: =_xlfn.STDEV.S(OFFSET(prevalence_total!K:K,1,0,COUNTA(prevalence_total!K:K)-1)) -> 0 | AD10: =_xlfn.STDEV.S(OFFSET(prevalence_total!L:L,1,0,COUNTA(prevalence_total!L:L)-1)) -> 0 | AE10: =_xlfn.STDEV.S(OFFSET(prevalence_total!M:M,1,0,COUNTA(prevalence_total!M:M)-1)) -> 0 | AF10: =_xlfn.STDEV.S(OFFSET(prevalence_total!N:N,1,0,COUNTA(prevalence_total!N:N)-1)) -> 0 | AG10: =_xlfn.STDEV.S(OFFSET(prevalence_total!O:O,1,0,COUNTA(prevalence_total!O:O)-1)) -> 0 | AI10: Total | AJ10: Validation | AK10: 0 | AL10: =1.96*U10/SQRT(COUNT(incidence_cadaver!B:B)-1) -> #DIV/0! | AM10: =1.96*V10/SQRT(COUNT(incidence_cadaver!C:C)-1) -> #DIV/0! | AN10: =1.96*W10/SQRT(COUNT(incidence_cadaver!D:D)-1) -> #DIV/0! | AO10: =1.96*X10/SQRT(COUNT(incidence_cadaver!E:E)-1) -> #DIV/0! | AP10: =1.96*Y10/SQRT(COUNT(incidence_cadaver!F:F)-1) -> #DIV/0! | AQ10: =1.96*Z10/SQRT(COUNT(incidence_cadaver!G:G)-1) -> #DIV/0! | AR10: =1.96*AA10/SQRT(COUNT(incidence_cadaver!H:H)-1) -> #DIV/0! | AS10: =1.96*AB10/SQRT(COUNT(incidence_cadaver!I:I)-1) -> #DIV/0! | AT10: =1.96*AC10/SQRT(COUNT(incidence_cadaver!J:J)-1) -> #DIV/0! | AU10: =1.96*AD10/SQRT(COUNT(incidence_cadaver!K:K)-1) -> #DIV/0! | AV10: =1.96*AE10/SQRT(COUNT(incidence_cadaver!L:L)-1) -> #DIV/0! | AW10: =1.96*AF10/SQRT(COUNT(incidence_cadaver!M:M)-1) -> #DIV/0! | AX10: =1.96*AG10/SQRT(COUNT(incidence_cadaver!N:N)-1) -> #DIV/0!
A11: Cadaver | B11: Validation | C11: =AVERAGE(OFFSET(prevalence_cadaver!B:B,1,0,COUNTA(prevalence_cadaver!B:B)-1)) -> #REF! | D11: =AVERAGE(OFFSET(prevalence_cadaver!C:C,1,0,COUNTA(prevalence_cadaver!C:C)-1)) -> #REF! | E11: =AVERAGE(OFFSET(prevalence_cadaver!D:D,1,0,COUNTA(prevalence_cadaver!D:D)-1)) -> #REF! | F11: =AVERAGE(OFFSET(prevalence_cadaver!E:E,1,0,COUNTA(prevalence_cadaver!E:E)-1)) -> #REF! | G11: =AVERAGE(OFFSET(prevalence_cadaver!F:F,1,0,COUNTA(prevalence_cadaver!F:F)-1)) -> #REF! | H11: =AVERAGE(OFFSET(prevalence_cadaver!G:G,1,0,COUNTA(prevalence_cadaver!G:G)-1)) -> #REF! | I11: =AVERAGE(OFFSET(prevalence_cadaver!H:H,1,0,COUNTA(prevalence_cadaver!H:H)-1)) -> #REF! | J11: =AVERAGE(OFFSET(prevalence_cadaver!I:I,1,0,COUNTA(prevalence_cadaver!I:I)-1)) -> #REF! | K11: =AVERAGE(OFFSET(prevalence_cadaver!J:J,1,0,COUNTA(prevalence_cadaver!J:J)-1)) -> #REF! | L11: =AVERAGE(OFFSET(prevalence_cadaver!K:K,1,0,COUNTA(prevalence_cadaver!K:K)-1)) -> #REF! | M11: =AVERAGE(OFFSET(prevalence_cadaver!L:L,1,0,COUNTA(prevalence_cadaver!L:L)-1)) -> #REF! | N11: =AVERAGE(OFFSET(prevalence_cadaver!M:M,1,0,COUNTA(prevalence_cadaver!M:M)-1)) -> #REF! | O11: =AVERAGE(OFFSET(prevalence_cadaver!N:N,1,0,COUNTA(prevalence_cadaver!N:N)-1)) -> #REF! | P11: =AVERAGE(OFFSET(prevalence_cadaver!O:O,1,0,COUNTA(prevalence_cadaver!O:O)-1)) -> #REF! | R11: Cadaver | S11: Validation | T11: =_xlfn.STDEV.S(OFFSET(prevalence_cadaver!B:B,1,0,COUNTA(prevalence_cadaver!B:B)-1)) -> #REF! | U11: =_xlfn.STDEV.S(OFFSET(prevalence_cadaver!C:C,1,0,COUNTA(prevalence_cadaver!C:C)-1)) -> #REF! | V11: =_xlfn.STDEV.S(OFFSET(prevalence_cadaver!D:D,1,0,COUNTA(prevalence_cadaver!D:D)-1)) -> #REF! | W11: =_xlfn.STDEV.S(OFFSET(prevalence_cadaver!E:E,1,0,COUNTA(prevalence_cadaver!E:E)-1)) -> #REF! | X11: =_xlfn.STDEV.S(OFFSET(prevalence_cadaver!F:F,1,0,COUNTA(prevalence_cadaver!F:F)-1)) -> #REF! | Y11: =_xlfn.STDEV.S(OFFSET(prevalence_cadaver!G:G,1,0,COUNTA(prevalence_cadaver!G:G)-1)) -> #REF! | Z11: =_xlfn.STDEV.S(OFFSET(prevalence_cadaver!H:H,1,0,COUNTA(prevalence_cadaver!H:H)-1)) -> #REF! | AA11: =_xlfn.STDEV.S(OFFSET(prevalence_cadaver!I:I,1,0,COUNTA(prevalence_cadaver!I:I)-1)) -> #REF! | AB11: =_xlfn.STDEV.S(OFFSET(prevalence_cadaver!J:J,1,0,COUNTA(prevalence_cadaver!J:J)-1)) -> #REF! | AC11: =_xlfn.STDEV.S(OFFSET(prevalence_cadaver!K:K,1,0,COUNTA(prevalence_cadaver!K:K)-1)) -> #REF! | AD11: =_xlfn.STDEV.S(OFFSET(prevalence_cadaver!L:L,1,0,COUNTA(prevalence_cadaver!L:L)-1)) -> #REF! | AE11: =_xlfn.STDEV.S(OFFSET(prevalence_cadaver!M:M,1,0,COUNTA(prevalence_cadaver!M:M)-1)) -> #REF! | AF11: =_xlfn.STDEV.S(OFFSET(prevalence_cadaver!N:N,1,0,COUNTA(prevalence_cadaver!N:N)-1)) -> #REF! | AG11: =_xlfn.STDEV.S(OFFSET(prevalence_cadaver!O:O,1,0,COUNTA(prevalence_cadaver!O:O)-1)) -> #REF! | AI11: Cadaver | AJ11: Validation | AK11: 0 | AL11: =1.96*U11/SQRT(COUNT(incidence_cadaver!B:B)-1) -> #REF! | AM11: =1.96*V11/SQRT(COUNT(incidence_cadaver!C:C)-1) -> #REF! | AN11: =1.96*W11/SQRT(COUNT(incidence_cadaver!D:D)-1) -> #REF! | AO11: =1.96*X11/SQRT(COUNT(incidence_cadaver!E:E)-1) -> #REF! | AP11: =1.96*Y11/SQRT(COUNT(incidence_cadaver!F:F)-1) -> #REF! | AQ11: =1.96*Z11/SQRT(COUNT(incidence_cadaver!G:G)-1) -> #REF! | AR11: =1.96*AA11/SQRT(COUNT(incidence_cadaver!H:H)-1) -> #REF! | AS11: =1.96*AB11/SQRT(COUNT(incidence_cadaver!I:I)-1) -> #REF! | AT11: =1.96*AC11/SQRT(COUNT(incidence_cadaver!J:J)-1) -> #REF! | AU11: =1.96*AD11/SQRT(COUNT(incidence_cadaver!K:K)-1) -> #REF! | AV11: =1.96*AE11/SQRT(COUNT(incidence_cadaver!L:L)-1) -> #REF! | AW11: =1.96*AF11/SQRT(COUNT(incidence_cadaver!M:M)-1) -> #REF! | AX11: =1.96*AG11/SQRT(COUNT(incidence_cadaver!N:N)-1) -> #REF!
A12: Live | B12: Validation | C12: =AVERAGE(OFFSET(prevalence_live!B:B,1,0,COUNTA(prevalence_live!B:B)-1)) -> #REF! | D12: =AVERAGE(OFFSET(prevalence_live!C:C,1,0,COUNTA(prevalence_live!C:C)-1)) -> #REF! | E12: =AVERAGE(OFFSET(prevalence_live!D:D,1,0,COUNTA(prevalence_live!D:D)-1)) -> #REF! | F12: =AVERAGE(OFFSET(prevalence_live!E:E,1,0,COUNTA(prevalence_live!E:E)-1)) -> #REF! | G12: =AVERAGE(OFFSET(prevalence_live!F:F,1,0,COUNTA(prevalence_live!F:F)-1)) -> #REF! | H12: =AVERAGE(OFFSET(prevalence_live!G:G,1,0,COUNTA(prevalence_live!G:G)-1)) -> #REF! | I12: =AVERAGE(OFFSET(prevalence_live!H:H,1,0,COUNTA(prevalence_live!H:H)-1)) -> #REF! | J12: =AVERAGE(OFFSET(prevalence_live!I:I,1,0,COUNTA(prevalence_live!I:I)-1)) -> #REF! | K12: =AVERAGE(OFFSET(prevalence_live!J:J,1,0,COUNTA(prevalence_live!J:J)-1)) -> #REF! | L12: =AVERAGE(OFFSET(prevalence_live!K:K,1,0,COUNTA(prevalence_live!K:K)-1)) -> #REF! | M12: =AVERAGE(OFFSET(prevalence_live!L:L,1,0,COUNTA(prevalence_live!L:L)-1)) -> #REF! | N12: =AVERAGE(OFFSET(prevalence_live!M:M,1,0,COUNTA(prevalence_live!M:M)-1)) -> #REF! | O12: =AVERAGE(OFFSET(prevalence_live!N:N,1,0,COUNTA(prevalence_live!N:N)-1)) -> #REF! | P12: =AVERAGE(OFFSET(prevalence_live!O:O,1,0,COUNTA(prevalence_live!O:O)-1)) -> #REF! | R12: Live | S12: Validation | T12: =_xlfn.STDEV.S(OFFSET(prevalence_live!B:B,1,0,COUNTA(prevalence_live!B:B)-1)) -> #REF! | U12: =_xlfn.STDEV.S(OFFSET(prevalence_live!C:C,1,0,COUNTA(prevalence_live!C:C)-1)) -> #REF! | V12: =_xlfn.STDEV.S(OFFSET(prevalence_live!D:D,1,0,COUNTA(prevalence_live!D:D)-1)) -> #REF! | W12: =_xlfn.STDEV.S(OFFSET(prevalence_live!E:E,1,0,COUNTA(prevalence_live!E:E)-1)) -> #REF! | X12: =_xlfn.STDEV.S(OFFSET(prevalence_live!F:F,1,0,COUNTA(prevalence_live!F:F)-1)) -> #REF! | Y12: =_xlfn.STDEV.S(OFFSET(prevalence_live!G:G,1,0,COUNTA(prevalence_live!G:G)-1)) -> #REF! | Z12: =_xlfn.STDEV.S(OFFSET(prevalence_live!H:H,1,0,COUNTA(prevalence_live!H:H)-1)) -> #REF! | AA12: =_xlfn.STDEV.S(OFFSET(prevalence_live!I:I,1,0,COUNTA(prevalence_live!I:I)-1)) -> #REF! | AB12: =_xlfn.STDEV.S(OFFSET(prevalence_live!J:J,1,0,COUNTA(prevalence_live!J:J)-1)) -> #REF! | AC12: =_xlfn.STDEV.S(OFFSET(prevalence_live!K:K,1,0,COUNTA(prevalence_live!K:K)-1)) -> #REF! | AD12: =_xlfn.STDEV.S(OFFSET(prevalence_live!L:L,1,0,COUNTA(prevalence_live!L:L)-1)) -> #REF! | AE12: =_xlfn.STDEV.S(OFFSET(prevalence_live!M:M,1,0,COUNTA(prevalence_live!M:M)-1)) -> #REF! | AF12: =_xlfn.STDEV.S(OFFSET(prevalence_live!N:N,1,0,COUNTA(prevalence_live!N:N)-1)) -> #REF! | AG12: =_xlfn.STDEV.S(OFFSET(prevalence_live!O:O,1,0,COUNTA(prevalence_live!O:O)-1)) -> #REF! | AI12: Live | AJ12: Validation | AK12: 0 | AL12: =1.96*U12/SQRT(COUNT(incidence_cadaver!B:B)-1) -> #REF! | AM12: =1.96*V12/SQRT(COUNT(incidence_cadaver!C:C)-1) -> #REF! | AN12: =1.96*W12/SQRT(COUNT(incidence_cadaver!D:D)-1) -> #REF! | AO12: =1.96*X12/SQRT(COUNT(incidence_cadaver!E:E)-1) -> #REF! | AP12: =1.96*Y12/SQRT(COUNT(incidence_cadaver!F:F)-1) -> #REF! | AQ12: =1.96*Z12/SQRT(COUNT(incidence_cadaver!G:G)-1) -> #REF! | AR12: =1.96*AA12/SQRT(COUNT(incidence_cadaver!H:H)-1) -> #REF! | AS12: =1.96*AB12/SQRT(COUNT(incidence_cadaver!I:I)-1) -> #REF! | AT12: =1.96*AC12/SQRT(COUNT(incidence_cadaver!J:J)-1) -> #REF! | AU12: =1.96*AD12/SQRT(COUNT(incidence_cadaver!K:K)-1) -> #REF! | AV12: =1.96*AE12/SQRT(COUNT(incidence_cadaver!L:L)-1) -> #REF! | AW12: =1.96*AF12/SQRT(COUNT(incidence_cadaver!M:M)-1) -> #REF! | AX12: =1.96*AG12/SQRT(COUNT(incidence_cadaver!N:N)-1) -> #REF!
A13: ICHD | B13: Validation | C13: =AVERAGE(OFFSET(prevalence_ichd!B:B,1,0,COUNTA(prevalence_ichd!B:B)-1)) -> #REF! | D13: =AVERAGE(OFFSET(prevalence_ichd!C:C,1,0,COUNTA(prevalence_ichd!C:C)-1)) -> #REF! | E13: =AVERAGE(OFFSET(prevalence_ichd!D:D,1,0,COUNTA(prevalence_ichd!D:D)-1)) -> #REF! | F13: =AVERAGE(OFFSET(prevalence_ichd!E:E,1,0,COUNTA(prevalence_ichd!E:E)-1)) -> #REF! | G13: =AVERAGE(OFFSET(prevalence_ichd!F:F,1,0,COUNTA(prevalence_ichd!F:F)-1)) -> #REF! | H13: =AVERAGE(OFFSET(prevalence_ichd!G:G,1,0,COUNTA(prevalence_ichd!G:G)-1)) -> #REF! | I13: =AVERAGE(OFFSET(prevalence_ichd!H:H,1,0,COUNTA(prevalence_ichd!H:H)-1)) -> #REF! | J13: =AVERAGE(OFFSET(prevalence_ichd!I:I,1,0,COUNTA(prevalence_ichd!I:I)-1)) -> #REF! | K13: =AVERAGE(OFFSET(prevalence_ichd!J:J,1,0,COUNTA(prevalence_ichd!J:J)-1)) -> #REF! | L13: =AVERAGE(OFFSET(prevalence_ichd!K:K,1,0,COUNTA(prevalence_ichd!K:K)-1)) -> #REF! | M13: =AVERAGE(OFFSET(prevalence_ichd!L:L,1,0,COUNTA(prevalence_ichd!L:L)-1)) -> #REF! | N13: =AVERAGE(OFFSET(prevalence_ichd!M:M,1,0,COUNTA(prevalence_ichd!M:M)-1)) -> #REF! | O13: =AVERAGE(OFFSET(prevalence_ichd!N:N,1,0,COUNTA(prevalence_ichd!N:N)-1)) -> #REF! | P13: =AVERAGE(OFFSET(prevalence_ichd!O:O,1,0,COUNTA(prevalence_ichd!O:O)-1)) -> #REF! | R13: ICHD | S13: Validation | T13: =_xlfn.STDEV.S(OFFSET(prevalence_ichd!B:B,1,0,COUNTA(prevalence_ichd!B:B)-1)) -> #REF! | U13: =_xlfn.STDEV.S(OFFSET(prevalence_ichd!C:C,1,0,COUNTA(prevalence_ichd!C:C)-1)) -> #REF! | V13: =_xlfn.STDEV.S(OFFSET(prevalence_ichd!D:D,1,0,COUNTA(prevalence_ichd!D:D)-1)) -> #REF! | W13: =_xlfn.STDEV.S(OFFSET(prevalence_ichd!E:E,1,0,COUNTA(prevalence_ichd!E:E)-1)) -> #REF! | X13: =_xlfn.STDEV.S(OFFSET(prevalence_ichd!F:F,1,0,COUNTA(prevalence_ichd!F:F)-1)) -> #REF! | Y13: =_xlfn.STDEV.S(OFFSET(prevalence_ichd!G:G,1,0,COUNTA(prevalence_ichd!G:G)-1)) -> #REF! | Z13: =_xlfn.STDEV.S(OFFSET(prevalence_ichd!H:H,1,0,COUNTA(prevalence_ichd!H:H)-1)) -> #REF! | AA13: =_xlfn.STDEV.S(OFFSET(prevalence_ichd!I:I,1,0,COUNTA(prevalence_ichd!I:I)-1)) -> #REF! | AB13: =_xlfn.STDEV.S(OFFSET(prevalence_ichd!J:J,1,0,COUNTA(prevalence_ichd!J:J)-1)) -> #REF! | AC13: =_xlfn.STDEV.S(OFFSET(prevalence_ichd!K:K,1,0,COUNTA(prevalence_ichd!K:K)-1)) -> #REF! | AD13: =_xlfn.STDEV.S(OFFSET(prevalence_ichd!L:L,1,0,COUNTA(prevalence_ichd!L:L)-1)) -> #REF! | AE13: =_xlfn.STDEV.S(OFFSET(prevalence_ichd!M:M,1,0,COUNTA(prevalence_ichd!M:M)-1)) -> #REF! | AF13: =_xlfn.STDEV.S(OFFSET(prevalence_ichd!N:N,1,0,COUNTA(prevalence_ichd!N:N)-1)) -> #REF! | AG13: =_xlfn.STDEV.S(OFFSET(prevalence_ichd!O:O,1,0,COUNTA(prevalence_ichd!O:O)-1)) -> #REF! | AI13: ICHD | AJ13: Validation | AK13: 0 | AL13: =1.96*U13/SQRT(COUNT(incidence_cadaver!B:B)-1) -> #REF! | AM13: =1.96*V13/SQRT(COUNT(incidence_cadaver!C:C)-1) -> #REF! | AN13: =1.96*W13/SQRT(COUNT(incidence_cadaver!D:D)-1) -> #REF! | AO13: =1.96*X13/SQRT(COUNT(incidence_cadaver!E:E)-1) -> #REF! | AP13: =1.96*Y13/SQRT(COUNT(incidence_cadaver!F:F)-1) -> #REF! | AQ13: =1.96*Z13/SQRT(COUNT(incidence_cadaver!G:G)-1) -> #REF! | AR13: =1.96*AA13/SQRT(COUNT(incidence_cadaver!H:H)-1) -> #REF! | AS13: =1.96*AB13/SQRT(COUNT(incidence_cadaver!I:I)-1) -> #REF! | AT13: =1.96*AC13/SQRT(COUNT(incidence_cadaver!J:J)-1) -> #REF! | AU13: =1.96*AD13/SQRT(COUNT(incidence_cadaver!K:K)-1) -> #REF! | AV13: =1.96*AE13/SQRT(COUNT(incidence_cadaver!L:L)-1) -> #REF! | AW13: =1.96*AF13/SQRT(COUNT(incidence_cadaver!M:M)-1) -> #REF! | AX13: =1.96*AG13/SQRT(COUNT(incidence_cadaver!N:N)-1) -> #REF!
A14: HHD | B14: Validation | C14: =AVERAGE(OFFSET(prevalence_hhd!B:B,1,0,COUNTA(prevalence_hhd!B:B)-1)) -> #REF! | D14: =AVERAGE(OFFSET(prevalence_hhd!C:C,1,0,COUNTA(prevalence_hhd!C:C)-1)) -> #REF! | E14: =AVERAGE(OFFSET(prevalence_hhd!D:D,1,0,COUNTA(prevalence_hhd!D:D)-1)) -> #REF! | F14: =AVERAGE(OFFSET(prevalence_hhd!E:E,1,0,COUNTA(prevalence_hhd!E:E)-1)) -> #REF! | G14: =AVERAGE(OFFSET(prevalence_hhd!F:F,1,0,COUNTA(prevalence_hhd!F:F)-1)) -> #REF! | H14: =AVERAGE(OFFSET(prevalence_hhd!G:G,1,0,COUNTA(prevalence_hhd!G:G)-1)) -> #REF! | I14: =AVERAGE(OFFSET(prevalence_hhd!H:H,1,0,COUNTA(prevalence_hhd!H:H)-1)) -> #REF! | J14: =AVERAGE(OFFSET(prevalence_hhd!I:I,1,0,COUNTA(prevalence_hhd!I:I)-1)) -> #REF! | K14: =AVERAGE(OFFSET(prevalence_hhd!J:J,1,0,COUNTA(prevalence_hhd!J:J)-1)) -> #REF! | L14: =AVERAGE(OFFSET(prevalence_hhd!K:K,1,0,COUNTA(prevalence_hhd!K:K)-1)) -> #REF! | M14: =AVERAGE(OFFSET(prevalence_hhd!L:L,1,0,COUNTA(prevalence_hhd!L:L)-1)) -> #REF! | N14: =AVERAGE(OFFSET(prevalence_hhd!M:M,1,0,COUNTA(prevalence_hhd!M:M)-1)) -> #REF! | O14: =AVERAGE(OFFSET(prevalence_hhd!N:N,1,0,COUNTA(prevalence_hhd!N:N)-1)) -> #REF! | P14: =AVERAGE(OFFSET(prevalence_hhd!O:O,1,0,COUNTA(prevalence_hhd!O:O)-1)) -> #REF! | R14: HHD | S14: Validation | T14: =_xlfn.STDEV.S(OFFSET(prevalence_hhd!B:B,1,0,COUNTA(prevalence_hhd!B:B)-1)) -> #REF! | U14: =_xlfn.STDEV.S(OFFSET(prevalence_hhd!C:C,1,0,COUNTA(prevalence_hhd!C:C)-1)) -> #REF! | V14: =_xlfn.STDEV.S(OFFSET(prevalence_hhd!D:D,1,0,COUNTA(prevalence_hhd!D:D)-1)) -> #REF! | W14: =_xlfn.STDEV.S(OFFSET(prevalence_hhd!E:E,1,0,COUNTA(prevalence_hhd!E:E)-1)) -> #REF! | X14: =_xlfn.STDEV.S(OFFSET(prevalence_hhd!F:F,1,0,COUNTA(prevalence_hhd!F:F)-1)) -> #REF! | Y14: =_xlfn.STDEV.S(OFFSET(prevalence_hhd!G:G,1,0,COUNTA(prevalence_hhd!G:G)-1)) -> #REF! | Z14: =_xlfn.STDEV.S(OFFSET(prevalence_hhd!H:H,1,0,COUNTA(prevalence_hhd!H:H)-1)) -> #REF! | AA14: =_xlfn.STDEV.S(OFFSET(prevalence_hhd!I:I,1,0,COUNTA(prevalence_hhd!I:I)-1)) -> #REF! | AB14: =_xlfn.STDEV.S(OFFSET(prevalence_hhd!J:J,1,0,COUNTA(prevalence_hhd!J:J)-1)) -> #REF! | AC14: =_xlfn.STDEV.S(OFFSET(prevalence_hhd!K:K,1,0,COUNTA(prevalence_hhd!K:K)-1)) -> #REF! | AD14: =_xlfn.STDEV.S(OFFSET(prevalence_hhd!L:L,1,0,COUNTA(prevalence_hhd!L:L)-1)) -> #REF! | AE14: =_xlfn.STDEV.S(OFFSET(prevalence_hhd!M:M,1,0,COUNTA(prevalence_hhd!M:M)-1)) -> #REF! | AF14: =_xlfn.STDEV.S(OFFSET(prevalence_hhd!N:N,1,0,COUNTA(prevalence_hhd!N:N)-1)) -> #REF! | AG14: =_xlfn.STDEV.S(OFFSET(prevalence_hhd!O:O,1,0,COUNTA(prevalence_hhd!O:O)-1)) -> #REF! | AI14: HHD | AJ14: Validation | AK14: 0 | AL14: =1.96*U14/SQRT(COUNT(incidence_cadaver!B:B)-1) -> #REF! | AM14: =1.96*V14/SQRT(COUNT(incidence_cadaver!C:C)-1) -> #REF! | AN14: =1.96*W14/SQRT(COUNT(incidence_cadaver!D:D)-1) -> #REF! | AO14: =1.96*X14/SQRT(COUNT(incidence_cadaver!E:E)-1) -> #REF! | AP14: =1.96*Y14/SQRT(COUNT(incidence_cadaver!F:F)-1) -> #REF! | AQ14: =1.96*Z14/SQRT(COUNT(incidence_cadaver!G:G)-1) -> #REF! | AR14: =1.96*AA14/SQRT(COUNT(incidence_cadaver!H:H)-1) -> #REF! | AS14: =1.96*AB14/SQRT(COUNT(incidence_cadaver!I:I)-1) -> #REF! | AT14: =1.96*AC14/SQRT(COUNT(incidence_cadaver!J:J)-1) -> #REF! | AU14: =1.96*AD14/SQRT(COUNT(incidence_cadaver!K:K)-1) -> #REF! | AV14: =1.96*AE14/SQRT(COUNT(incidence_cadaver!L:L)-1) -> #REF! | AW14: =1.96*AF14/SQRT(COUNT(incidence_cadaver!M:M)-1) -> #REF! | AX14: =1.96*AG14/SQRT(COUNT(incidence_cadaver!N:N)-1) -> #REF!
A15: PD | B15: Validation | C15: =AVERAGE(OFFSET(prevalence_pd!B:B,1,0,COUNTA(prevalence_pd!B:B)-1)) -> #REF! | D15: =AVERAGE(OFFSET(prevalence_pd!C:C,1,0,COUNTA(prevalence_pd!C:C)-1)) -> #REF! | E15: =AVERAGE(OFFSET(prevalence_pd!D:D,1,0,COUNTA(prevalence_pd!D:D)-1)) -> #REF! | F15: =AVERAGE(OFFSET(prevalence_pd!E:E,1,0,COUNTA(prevalence_pd!E:E)-1)) -> #REF! | G15: =AVERAGE(OFFSET(prevalence_pd!F:F,1,0,COUNTA(prevalence_pd!F:F)-1)) -> #REF! | H15: =AVERAGE(OFFSET(prevalence_pd!G:G,1,0,COUNTA(prevalence_pd!G:G)-1)) -> #REF! | I15: =AVERAGE(OFFSET(prevalence_pd!H:H,1,0,COUNTA(prevalence_pd!H:H)-1)) -> #REF! | J15: =AVERAGE(OFFSET(prevalence_pd!I:I,1,0,COUNTA(prevalence_pd!I:I)-1)) -> #REF! | K15: =AVERAGE(OFFSET(prevalence_pd!J:J,1,0,COUNTA(prevalence_pd!J:J)-1)) -> #REF! | L15: =AVERAGE(OFFSET(prevalence_pd!K:K,1,0,COUNTA(prevalence_pd!K:K)-1)) -> #REF! | M15: =AVERAGE(OFFSET(prevalence_pd!L:L,1,0,COUNTA(prevalence_pd!L:L)-1)) -> #REF! | N15: =AVERAGE(OFFSET(prevalence_pd!M:M,1,0,COUNTA(prevalence_pd!M:M)-1)) -> #REF! | O15: =AVERAGE(OFFSET(prevalence_pd!N:N,1,0,COUNTA(prevalence_pd!N:N)-1)) -> #REF! | P15: =AVERAGE(OFFSET(prevalence_pd!O:O,1,0,COUNTA(prevalence_pd!O:O)-1)) -> #REF! | R15: PD | S15: Validation | T15: =_xlfn.STDEV.S(OFFSET(prevalence_pd!B:B,1,0,COUNTA(prevalence_pd!B:B)-1)) -> #REF! | U15: =_xlfn.STDEV.S(OFFSET(prevalence_pd!C:C,1,0,COUNTA(prevalence_pd!C:C)-1)) -> #REF! | V15: =_xlfn.STDEV.S(OFFSET(prevalence_pd!D:D,1,0,COUNTA(prevalence_pd!D:D)-1)) -> #REF! | W15: =_xlfn.STDEV.S(OFFSET(prevalence_pd!E:E,1,0,COUNTA(prevalence_pd!E:E)-1)) -> #REF! | X15: =_xlfn.STDEV.S(OFFSET(prevalence_pd!F:F,1,0,COUNTA(prevalence_pd!F:F)-1)) -> #REF! | Y15: =_xlfn.STDEV.S(OFFSET(prevalence_pd!G:G,1,0,COUNTA(prevalence_pd!G:G)-1)) -> #REF! | Z15: =_xlfn.STDEV.S(OFFSET(prevalence_pd!H:H,1,0,COUNTA(prevalence_pd!H:H)-1)) -> #REF! | AA15: =_xlfn.STDEV.S(OFFSET(prevalence_pd!I:I,1,0,COUNTA(prevalence_pd!I:I)-1)) -> #REF! | AB15: =_xlfn.STDEV.S(OFFSET(prevalence_pd!J:J,1,0,COUNTA(prevalence_pd!J:J)-1)) -> #REF! | AC15: =_xlfn.STDEV.S(OFFSET(prevalence_pd!K:K,1,0,COUNTA(prevalence_pd!K:K)-1)) -> #REF! | AD15: =_xlfn.STDEV.S(OFFSET(prevalence_pd!L:L,1,0,COUNTA(prevalence_pd!L:L)-1)) -> #REF! | AE15: =_xlfn.STDEV.S(OFFSET(prevalence_pd!M:M,1,0,COUNTA(prevalence_pd!M:M)-1)) -> #REF! | AF15: =_xlfn.STDEV.S(OFFSET(prevalence_pd!N:N,1,0,COUNTA(prevalence_pd!N:N)-1)) -> #REF! | AG15: =_xlfn.STDEV.S(OFFSET(prevalence_pd!O:O,1,0,COUNTA(prevalence_pd!O:O)-1)) -> #REF! | AI15: PD | AJ15: Validation | AK15: 0 | AL15: =1.96*U15/SQRT(COUNT(incidence_cadaver!B:B)-1) -> #REF! | AM15: =1.96*V15/SQRT(COUNT(incidence_cadaver!C:C)-1) -> #REF! | AN15: =1.96*W15/SQRT(COUNT(incidence_cadaver!D:D)-1) -> #REF! | AO15: =1.96*X15/SQRT(COUNT(incidence_cadaver!E:E)-1) -> #REF! | AP15: =1.96*Y15/SQRT(COUNT(incidence_cadaver!F:F)-1) -> #REF! | AQ15: =1.96*Z15/SQRT(COUNT(incidence_cadaver!G:G)-1) -> #REF! | AR15: =1.96*AA15/SQRT(COUNT(incidence_cadaver!H:H)-1) -> #REF! | AS15: =1.96*AB15/SQRT(COUNT(incidence_cadaver!I:I)-1) -> #REF! | AT15: =1.96*AC15/SQRT(COUNT(incidence_cadaver!J:J)-1) -> #REF! | AU15: =1.96*AD15/SQRT(COUNT(incidence_cadaver!K:K)-1) -> #REF! | AV15: =1.96*AE15/SQRT(COUNT(incidence_cadaver!L:L)-1) -> #REF! | AW15: =1.96*AF15/SQRT(COUNT(incidence_cadaver!M:M)-1) -> #REF! | AX15: =1.96*AG15/SQRT(COUNT(incidence_cadaver!N:N)-1) -> #REF!
A17: Mortality | R17: Mortality | AI17: Mortality
A18: Total | B18: Validation | C18: =SUM(C19:C23) -> #REF! | D18: =SUM(D19:D23) -> #REF! | E18: =SUM(E19:E23) -> #REF! | F18: =SUM(F19:F23) -> #REF! | G18: =SUM(G19:G23) -> #REF! | H18: =SUM(H19:H23) -> #REF! | I18: =SUM(I19:I23) -> #REF! | J18: =SUM(J19:J23) -> #REF! | ... P18: =SUM(P19:P23) -> #REF! | R18: Total | S18: Validation | T18: =_xlfn.STDEV.S(OFFSET(mortality_total!B:B,1,0,COUNTA(mortality_total!B:B)-1)) -> 0 | U18: =_xlfn.STDEV.S(OFFSET(mortality_total!C:C,1,0,COUNTA(mortality_total!C:C)-1)) -> 0 | V18: =_xlfn.STDEV.S(OFFSET(mortality_total!D:D,1,0,COUNTA(mortality_total!D:D)-1)) -> 0 | W18: =_xlfn.STDEV.S(OFFSET(mortality_total!E:E,1,0,COUNTA(mortality_total!E:E)-1)) -> 0 | X18: =_xlfn.STDEV.S(OFFSET(mortality_total!F:F,1,0,COUNTA(mortality_total!F:F)-1)) -> 0 | Y18: =_xlfn.STDEV.S(OFFSET(mortality_total!G:G,1,0,COUNTA(mortality_total!G:G)-1)) -> 0 | Z18: =_xlfn.STDEV.S(OFFSET(mortality_total!H:H,1,0,COUNTA(mortality_total!H:H)-1)) -> 0 | AA18: =_xlfn.STDEV.S(OFFSET(mortality_total!I:I,1,0,COUNTA(mortality_total!I:I)-1)) -> 0 | AB18: =_xlfn.STDEV.S(OFFSET(mortality_total!J:J,1,0,COUNTA(mortality_total!J:J)-1)) -> 0 | AC18: =_xlfn.STDEV.S(OFFSET(mortality_total!K:K,1,0,COUNTA(mortality_total!K:K)-1)) -> 0 | AD18: =_xlfn.STDEV.S(OFFSET(mortality_total!L:L,1,0,COUNTA(mortality_total!L:L)-1)) -> 0 | AE18: =_xlfn.STDEV.S(OFFSET(mortality_total!M:M,1,0,COUNTA(mortality_total!M:M)-1)) -> 0 | AF18: =_xlfn.STDEV.S(OFFSET(mortality_total!N:N,1,0,COUNTA(mortality_total!N:N)-1)) -> 0 | AG18: =_xlfn.STDEV.S(OFFSET(mortality_total!O:O,1,0,COUNTA(mortality_total!O:O)-1)) -> 0 | AI18: Total | AJ18: Validation | AK18: 0 | AL18: =1.96*U18/SQRT(COUNT(incidence_cadaver!B:B)-1) -> #DIV/0! | AM18: =1.96*V18/SQRT(COUNT(incidence_cadaver!C:C)-1) -> #DIV/0! | AN18: =1.96*W18/SQRT(COUNT(incidence_cadaver!D:D)-1) -> #DIV/0! | AO18: =1.96*X18/SQRT(COUNT(incidence_cadaver!E:E)-1) -> #DIV/0! | AP18: =1.96*Y18/SQRT(COUNT(incidence_cadaver!F:F)-1) -> #DIV/0! | AQ18: =1.96*Z18/SQRT(COUNT(incidence_cadaver!G:G)-1) -> #DIV/0! | AR18: =1.96*AA18/SQRT(COUNT(incidence_cadaver!H:H)-1) -> #DIV/0! | AS18: =1.96*AB18/SQRT(COUNT(incidence_cadaver!I:I)-1) -> #DIV/0! | AT18: =1.96*AC18/SQRT(COUNT(incidence_cadaver!J:J)-1) -> #DIV/0! | AU18: =1.96*AD18/SQRT(COUNT(incidence_cadaver!K:K)-1) -> #DIV/0! | AV18: =1.96*AE18/SQRT(COUNT(incidence_cadaver!L:L)-1) -> #DIV/0! | AW18: =1.96*AF18/SQRT(COUNT(incidence_cadaver!M:M)-1) -> #DIV/0! | AX18: =1.96*AG18/SQRT(COUNT(incidence_cadaver!N:N)-1) -> #DIV/0!
A19: Cadaver | B19: Validation | C19: =AVERAGE(OFFSET(mortality_cadaver!B:B,1,0,COUNTA(mortality_cadaver!B:B)-1)) -> #REF! | D19: =AVERAGE(OFFSET(mortality_cadaver!C:C,1,0,COUNTA(mortality_cadaver!C:C)-1)) -> #REF! | E19: =AVERAGE(OFFSET(mortality_cadaver!D:D,1,0,COUNTA(mortality_cadaver!D:D)-1)) -> #REF! | F19: =AVERAGE(OFFSET(mortality_cadaver!E:E,1,0,COUNTA(mortality_cadaver!E:E)-1)) -> #REF! | G19: =AVERAGE(OFFSET(mortality_cadaver!F:F,1,0,COUNTA(mortality_cadaver!F:F)-1)) -> #REF! | H19: =AVERAGE(OFFSET(mortality_cadaver!G:G,1,0,COUNTA(mortality_cadaver!G:G)-1)) -> #REF! | I19: =AVERAGE(OFFSET(mortality_cadaver!H:H,1,0,COUNTA(mortality_cadaver!H:H)-1)) -> #REF! | J19: =AVERAGE(OFFSET(mortality_cadaver!I:I,1,0,COUNTA(mortality_cadaver!I:I)-1)) -> #REF! | K19: =AVERAGE(OFFSET(mortality_cadaver!J:J,1,0,COUNTA(mortality_cadaver!J:J)-1)) -> #REF! | L19: =AVERAGE(OFFSET(mortality_cadaver!K:K,1,0,COUNTA(mortality_cadaver!K:K)-1)) -> #REF! | M19: =AVERAGE(OFFSET(mortality_cadaver!L:L,1,0,COUNTA(mortality_cadaver!L:L)-1)) -> #REF! | N19: =AVERAGE(OFFSET(mortality_cadaver!M:M,1,0,COUNTA(mortality_cadaver!M:M)-1)) -> #REF! | O19: =AVERAGE(OFFSET(mortality_cadaver!N:N,1,0,COUNTA(mortality_cadaver!N:N)-1)) -> #REF! | P19: =AVERAGE(OFFSET(mortality_cadaver!O:O,1,0,COUNTA(mortality_cadaver!O:O)-1)) -> #REF! | R19: Cadaver | S19: Validation | T19: =_xlfn.STDEV.S(OFFSET(mortality_cadaver!B:B,1,0,COUNTA(mortality_cadaver!B:B)-1)) -> #REF! | U19: =_xlfn.STDEV.S(OFFSET(mortality_cadaver!C:C,1,0,COUNTA(mortality_cadaver!C:C)-1)) -> #REF! | V19: =_xlfn.STDEV.S(OFFSET(mortality_cadaver!D:D,1,0,COUNTA(mortality_cadaver!D:D)-1)) -> #REF! | W19: =_xlfn.STDEV.S(OFFSET(mortality_cadaver!E:E,1,0,COUNTA(mortality_cadaver!E:E)-1)) -> #REF! | X19: =_xlfn.STDEV.S(OFFSET(mortality_cadaver!F:F,1,0,COUNTA(mortality_cadaver!F:F)-1)) -> #REF! | Y19: =_xlfn.STDEV.S(OFFSET(mortality_cadaver!G:G,1,0,COUNTA(mortality_cadaver!G:G)-1)) -> #REF! | Z19: =_xlfn.STDEV.S(OFFSET(mortality_cadaver!H:H,1,0,COUNTA(mortality_cadaver!H:H)-1)) -> #REF! | AA19: =_xlfn.STDEV.S(OFFSET(mortality_cadaver!I:I,1,0,COUNTA(mortality_cadaver!I:I)-1)) -> #REF! | AB19: =_xlfn.STDEV.S(OFFSET(mortality_cadaver!J:J,1,0,COUNTA(mortality_cadaver!J:J)-1)) -> #REF! | AC19: =_xlfn.STDEV.S(OFFSET(mortality_cadaver!K:K,1,0,COUNTA(mortality_cadaver!K:K)-1)) -> #REF! | AD19: =_xlfn.STDEV.S(OFFSET(mortality_cadaver!L:L,1,0,COUNTA(mortality_cadaver!L:L)-1)) -> #REF! | AE19: =_xlfn.STDEV.S(OFFSET(mortality_cadaver!M:M,1,0,COUNTA(mortality_cadaver!M:M)-1)) -> #REF! | AF19: =_xlfn.STDEV.S(OFFSET(mortality_cadaver!N:N,1,0,COUNTA(mortality_cadaver!N:N)-1)) -> #REF! | AG19: =_xlfn.STDEV.S(OFFSET(mortality_cadaver!O:O,1,0,COUNTA(mortality_cadaver!O:O)-1)) -> #REF! | AI19: Cadaver | AJ19: Validation | AK19: 0 | AL19: =1.96*U19/SQRT(COUNT(incidence_cadaver!B:B)-1) -> #REF! | AM19: =1.96*V19/SQRT(COUNT(incidence_cadaver!C:C)-1) -> #REF! | AN19: =1.96*W19/SQRT(COUNT(incidence_cadaver!D:D)-1) -> #REF! | AO19: =1.96*X19/SQRT(COUNT(incidence_cadaver!E:E)-1) -> #REF! | AP19: =1.96*Y19/SQRT(COUNT(incidence_cadaver!F:F)-1) -> #REF! | AQ19: =1.96*Z19/SQRT(COUNT(incidence_cadaver!G:G)-1) -> #REF! | AR19: =1.96*AA19/SQRT(COUNT(incidence_cadaver!H:H)-1) -> #REF! | AS19: =1.96*AB19/SQRT(COUNT(incidence_cadaver!I:I)-1) -> #REF! | AT19: =1.96*AC19/SQRT(COUNT(incidence_cadaver!J:J)-1) -> #REF! | AU19: =1.96*AD19/SQRT(COUNT(incidence_cadaver!K:K)-1) -> #REF! | AV19: =1.96*AE19/SQRT(COUNT(incidence_cadaver!L:L)-1) -> #REF! | AW19: =1.96*AF19/SQRT(COUNT(incidence_cadaver!M:M)-1) -> #REF! | AX19: =1.96*AG19/SQRT(COUNT(incidence_cadaver!N:N)-1) -> #REF!
A20: Live | B20: Validation | C20: =AVERAGE(OFFSET(mortality_live!B:B,1,0,COUNTA(mortality_live!B:B)-1)) -> #REF! | D20: =AVERAGE(OFFSET(mortality_live!C:C,1,0,COUNTA(mortality_live!C:C)-1)) -> #REF! | E20: =AVERAGE(OFFSET(mortality_live!D:D,1,0,COUNTA(mortality_live!D:D)-1)) -> #REF! | F20: =AVERAGE(OFFSET(mortality_live!E:E,1,0,COUNTA(mortality_live!E:E)-1)) -> #REF! | G20: =AVERAGE(OFFSET(mortality_live!F:F,1,0,COUNTA(mortality_live!F:F)-1)) -> #REF! | H20: =AVERAGE(OFFSET(mortality_live!G:G,1,0,COUNTA(mortality_live!G:G)-1)) -> #REF! | I20: =AVERAGE(OFFSET(mortality_live!H:H,1,0,COUNTA(mortality_live!H:H)-1)) -> #REF! | J20: =AVERAGE(OFFSET(mortality_live!I:I,1,0,COUNTA(mortality_live!I:I)-1)) -> #REF! | K20: =AVERAGE(OFFSET(mortality_live!J:J,1,0,COUNTA(mortality_live!J:J)-1)) -> #REF! | L20: =AVERAGE(OFFSET(mortality_live!K:K,1,0,COUNTA(mortality_live!K:K)-1)) -> #REF! | M20: =AVERAGE(OFFSET(mortality_live!L:L,1,0,COUNTA(mortality_live!L:L)-1)) -> #REF! | N20: =AVERAGE(OFFSET(mortality_live!M:M,1,0,COUNTA(mortality_live!M:M)-1)) -> #REF! | O20: =AVERAGE(OFFSET(mortality_live!N:N,1,0,COUNTA(mortality_live!N:N)-1)) -> #REF! | P20: =AVERAGE(OFFSET(mortality_live!O:O,1,0,COUNTA(mortality_live!O:O)-1)) -> #REF! | R20: Live | S20: Validation | T20: =_xlfn.STDEV.S(OFFSET(mortality_live!B:B,1,0,COUNTA(mortality_live!B:B)-1)) -> #REF! | U20: =_xlfn.STDEV.S(OFFSET(mortality_live!C:C,1,0,COUNTA(mortality_live!C:C)-1)) -> #REF! | V20: =_xlfn.STDEV.S(OFFSET(mortality_live!D:D,1,0,COUNTA(mortality_live!D:D)-1)) -> #REF! | W20: =_xlfn.STDEV.S(OFFSET(mortality_live!E:E,1,0,COUNTA(mortality_live!E:E)-1)) -> #REF! | X20: =_xlfn.STDEV.S(OFFSET(mortality_live!F:F,1,0,COUNTA(mortality_live!F:F)-1)) -> #REF! | Y20: =_xlfn.STDEV.S(OFFSET(mortality_live!G:G,1,0,COUNTA(mortality_live!G:G)-1)) -> #REF! | Z20: =_xlfn.STDEV.S(OFFSET(mortality_live!H:H,1,0,COUNTA(mortality_live!H:H)-1)) -> #REF! | AA20: =_xlfn.STDEV.S(OFFSET(mortality_live!I:I,1,0,COUNTA(mortality_live!I:I)-1)) -> #REF! | AB20: =_xlfn.STDEV.S(OFFSET(mortality_live!J:J,1,0,COUNTA(mortality_live!J:J)-1)) -> #REF! | AC20: =_xlfn.STDEV.S(OFFSET(mortality_live!K:K,1,0,COUNTA(mortality_live!K:K)-1)) -> #REF! | AD20: =_xlfn.STDEV.S(OFFSET(mortality_live!L:L,1,0,COUNTA(mortality_live!L:L)-1)) -> #REF! | AE20: =_xlfn.STDEV.S(OFFSET(mortality_live!M:M,1,0,COUNTA(mortality_live!M:M)-1)) -> #REF! | AF20: =_xlfn.STDEV.S(OFFSET(mortality_live!N:N,1,0,COUNTA(mortality_live!N:N)-1)) -> #REF! | AG20: =_xlfn.STDEV.S(OFFSET(mortality_live!O:O,1,0,COUNTA(mortality_live!O:O)-1)) -> #REF! | AI20: Live | AJ20: Validation | AK20: 0 | AL20: =1.96*U20/SQRT(COUNT(incidence_cadaver!B:B)-1) -> #REF! | AM20: =1.96*V20/SQRT(COUNT(incidence_cadaver!C:C)-1) -> #REF! | AN20: =1.96*W20/SQRT(COUNT(incidence_cadaver!D:D)-1) -> #REF! | AO20: =1.96*X20/SQRT(COUNT(incidence_cadaver!E:E)-1) -> #REF! | AP20: =1.96*Y20/SQRT(COUNT(incidence_cadaver!F:F)-1) -> #REF! | AQ20: =1.96*Z20/SQRT(COUNT(incidence_cadaver!G:G)-1) -> #REF! | AR20: =1.96*AA20/SQRT(COUNT(incidence_cadaver!H:H)-1) -> #REF! | AS20: =1.96*AB20/SQRT(COUNT(incidence_cadaver!I:I)-1) -> #REF! | AT20: =1.96*AC20/SQRT(COUNT(incidence_cadaver!J:J)-1) -> #REF! | AU20: =1.96*AD20/SQRT(COUNT(incidence_cadaver!K:K)-1) -> #REF! | AV20: =1.96*AE20/SQRT(COUNT(incidence_cadaver!L:L)-1) -> #REF! | AW20: =1.96*AF20/SQRT(COUNT(incidence_cadaver!M:M)-1) -> #REF! | AX20: =1.96*AG20/SQRT(COUNT(incidence_cadaver!N:N)-1) -> #REF!
A21: ICHD | B21: Validation | C21: =AVERAGE(OFFSET(mortality_ichd!B:B,1,0,COUNTA(mortality_ichd!B:B)-1)) -> #REF! | D21: =AVERAGE(OFFSET(mortality_ichd!C:C,1,0,COUNTA(mortality_ichd!C:C)-1)) -> #REF! | E21: =AVERAGE(OFFSET(mortality_ichd!D:D,1,0,COUNTA(mortality_ichd!D:D)-1)) -> #REF! | F21: =AVERAGE(OFFSET(mortality_ichd!E:E,1,0,COUNTA(mortality_ichd!E:E)-1)) -> #REF! | G21: =AVERAGE(OFFSET(mortality_ichd!F:F,1,0,COUNTA(mortality_ichd!F:F)-1)) -> #REF! | H21: =AVERAGE(OFFSET(mortality_ichd!G:G,1,0,COUNTA(mortality_ichd!G:G)-1)) -> #REF! | I21: =AVERAGE(OFFSET(mortality_ichd!H:H,1,0,COUNTA(mortality_ichd!H:H)-1)) -> #REF! | J21: =AVERAGE(OFFSET(mortality_ichd!I:I,1,0,COUNTA(mortality_ichd!I:I)-1)) -> #REF! | K21: =AVERAGE(OFFSET(mortality_ichd!J:J,1,0,COUNTA(mortality_ichd!J:J)-1)) -> #REF! | L21: =AVERAGE(OFFSET(mortality_ichd!K:K,1,0,COUNTA(mortality_ichd!K:K)-1)) -> #REF! | M21: =AVERAGE(OFFSET(mortality_ichd!L:L,1,0,COUNTA(mortality_ichd!L:L)-1)) -> #REF! | N21: =AVERAGE(OFFSET(mortality_ichd!M:M,1,0,COUNTA(mortality_ichd!M:M)-1)) -> #REF! | O21: =AVERAGE(OFFSET(mortality_ichd!N:N,1,0,COUNTA(mortality_ichd!N:N)-1)) -> #REF! | P21: =AVERAGE(OFFSET(mortality_ichd!O:O,1,0,COUNTA(mortality_ichd!O:O)-1)) -> #REF! | R21: ICHD | S21: Validation | T21: =_xlfn.STDEV.S(OFFSET(mortality_ichd!B:B,1,0,COUNTA(mortality_ichd!B:B)-1)) -> #REF! | U21: =_xlfn.STDEV.S(OFFSET(mortality_ichd!C:C,1,0,COUNTA(mortality_ichd!C:C)-1)) -> #REF! | V21: =_xlfn.STDEV.S(OFFSET(mortality_ichd!D:D,1,0,COUNTA(mortality_ichd!D:D)-1)) -> #REF! | W21: =_xlfn.STDEV.S(OFFSET(mortality_ichd!E:E,1,0,COUNTA(mortality_ichd!E:E)-1)) -> #REF! | X21: =_xlfn.STDEV.S(OFFSET(mortality_ichd!F:F,1,0,COUNTA(mortality_ichd!F:F)-1)) -> #REF! | Y21: =_xlfn.STDEV.S(OFFSET(mortality_ichd!G:G,1,0,COUNTA(mortality_ichd!G:G)-1)) -> #REF! | Z21: =_xlfn.STDEV.S(OFFSET(mortality_ichd!H:H,1,0,COUNTA(mortality_ichd!H:H)-1)) -> #REF! | AA21: =_xlfn.STDEV.S(OFFSET(mortality_ichd!I:I,1,0,COUNTA(mortality_ichd!I:I)-1)) -> #REF! | AB21: =_xlfn.STDEV.S(OFFSET(mortality_ichd!J:J,1,0,COUNTA(mortality_ichd!J:J)-1)) -> #REF! | AC21: =_xlfn.STDEV.S(OFFSET(mortality_ichd!K:K,1,0,COUNTA(mortality_ichd!K:K)-1)) -> #REF! | AD21: =_xlfn.STDEV.S(OFFSET(mortality_ichd!L:L,1,0,COUNTA(mortality_ichd!L:L)-1)) -> #REF! | AE21: =_xlfn.STDEV.S(OFFSET(mortality_ichd!M:M,1,0,COUNTA(mortality_ichd!M:M)-1)) -> #REF! | AF21: =_xlfn.STDEV.S(OFFSET(mortality_ichd!N:N,1,0,COUNTA(mortality_ichd!N:N)-1)) -> #REF! | AG21: =_xlfn.STDEV.S(OFFSET(mortality_ichd!O:O,1,0,COUNTA(mortality_ichd!O:O)-1)) -> #REF! | AI21: ICHD | AJ21: Validation | AK21: 0 | AL21: =1.96*U21/SQRT(COUNT(incidence_cadaver!B:B)-1) -> #REF! | AM21: =1.96*V21/SQRT(COUNT(incidence_cadaver!C:C)-1) -> #REF! | AN21: =1.96*W21/SQRT(COUNT(incidence_cadaver!D:D)-1) -> #REF! | AO21: =1.96*X21/SQRT(COUNT(incidence_cadaver!E:E)-1) -> #REF! | AP21: =1.96*Y21/SQRT(COUNT(incidence_cadaver!F:F)-1) -> #REF! | AQ21: =1.96*Z21/SQRT(COUNT(incidence_cadaver!G:G)-1) -> #REF! | AR21: =1.96*AA21/SQRT(COUNT(incidence_cadaver!H:H)-1) -> #REF! | AS21: =1.96*AB21/SQRT(COUNT(incidence_cadaver!I:I)-1) -> #REF! | AT21: =1.96*AC21/SQRT(COUNT(incidence_cadaver!J:J)-1) -> #REF! | AU21: =1.96*AD21/SQRT(COUNT(incidence_cadaver!K:K)-1) -> #REF! | AV21: =1.96*AE21/SQRT(COUNT(incidence_cadaver!L:L)-1) -> #REF! | AW21: =1.96*AF21/SQRT(COUNT(incidence_cadaver!M:M)-1) -> #REF! | AX21: =1.96*AG21/SQRT(COUNT(incidence_cadaver!N:N)-1) -> #REF!
